File: sheets/100W.csv
[Measurement conditions],,,,,
Sample identification,,,,,
Comment - 1,"Configuration=Reflection-transmission spinner, Owner=User-1, Creation date=12/4/2012 10:13:13 AM",,,,
Comment - 2,Goniometer=Theta/Theta; Minimum step size 2Theta:0.0001; Minimum step size Omega:0.0001,,,,
Comment - 3,Sample stage=Reflection-transmission spinner; Minimum step size Phi:0.1,,,,
Comment - 4,Diffractometer system=EMPYREAN,,,,
Comment - 5,"Measurement program=C:\PANalytical\Data Collector\Programs\PI Lorenzo Mangolini\BrandonWagner_Mg.xrdmp, Identifier={9EE36770-7A59-4EAA-85D0-90E43AFBFC91}",,,,
Anode material,Cu,,,,
K-Alpha1 wavelength,1.540598,,,,
K-Alpha2 wavelength,1.544426,,,,
Ratio K-Alpha2/K-Alpha1,0.5,,,,
Divergence slit,Fixed,0.76mm,,,
Monochromator used,NO,,,,
Generator voltage,45,,,,
Tube current,40,,,,
File date and time,4/5/2023 16:05,,,,
Unit cell,,,,,
h k l, 0 0 0,,,,
Scan axis,Gonio,,,,
Scan range,20,79.99226154,,,
Scan step size,0.0393908,,,,
No. of points,1523,,,,
Scan type,CONTINUOUS,,,,
Phi,357.9,,,,
Time per step,45.135,,,,
[Scan points],,,,,
Angle, TimePerStep, Intensity, ESD,,
20.01969542,45.135,522,22.8473,5232,0.099770642
20.09847712,45.135,475,21.7945,,0.090787462
20.17725881,45.135,470,21.6795,,0.089831804
20.25604051,45.135,495,22.2486,,0.094610092
20.3348222,45.135,439,20.9523,,0.083906728
20.4136039,45.135,467,21.6102,,0.08925841
20.4923856,45.135,462,21.4942,,0.088302752
20.57116729,45.135,477,21.8403,,0.091169725
20.64994899,45.135,481,21.9317,,0.091934251
20.72873069,45.135,463,21.5174,,0.088493884
20.80751238,45.135,486,22.0454,,0.092889908
20.88629408,45.135,470,21.6795,,0.089831804
20.96507577,45.135,471,21.7025,,0.090022936
21.04385747,45.135,452,21.2603,,0.086391437
21.12263917,45.135,506,22.4944,,0.096712538
21.20142086,45.135,447,21.1424,,0.08543578
21.28020256,45.135,447,21.1424,,0.08543578
21.35898425,45.135,486,22.0454,,0.092889908
21.43776595,45.135,423,20.567,,0.080848624
21.51654765,45.135,472,21.7256,,0.090214067
21.59532934,45.135,421,20.5183,,0.080466361
21.67411104,45.135,473,21.7486,,0.090405199
21.75289273,45.135,462,21.4942,,0.088302752
21.83167443,45.135,464,21.5407,,0.088685015
21.91045613,45.135,485,22.0227,,0.092698777
21.98923782,45.135,446,21.1187,,0.085244648
22.06801952,45.135,447,21.1424,,0.08543578
22.14680121,45.135,446,21.1187,,0.085244648
22.22558291,45.135,420,20.4939,,0.080275229
22.30436461,45.135,435,20.8567,,0.083142202
22.3831463,45.135,443,21.0476,,0.084671254
22.461928,45.135,481,21.9317,,0.091934251
22.54070969,45.135,413,20.3224,,0.078937309
22.61949139,45.135,403,20.0749,,0.077025994
22.69827309,45.135,449,21.1896,,0.085818043
22.77705478,45.135,436,20.8806,,0.083333333
22.85583648,45.135,453,21.2838,,0.086582569
22.93461817,45.135,476,21.8174,,0.090978593
23.01339987,45.135,423,20.567,,0.080848624
23.09218157,45.135,455,21.3307,,0.086964832
23.17096326,45.135,454,21.3073,,0.0867737
23.24974496,45.135,410,20.2485,,0.078363914
23.32852665,45.135,495,22.2486,,0.094610092
23.40730835,45.135,419,20.4695,,0.080084098
23.48609005,45.135,435,20.8567,,0.083142202
23.56487174,45.135,438,20.9284,,0.083715596
23.64365344,45.135,422,20.5426,,0.080657492
23.72243514,45.135,415,20.3715,,0.079319572
23.80121683,45.135,435,20.8567,,0.083142202
23.87999853,45.135,426,20.6398,,0.081422018
23.95878022,45.135,449,21.1896,,0.085818043
24.03756192,45.135,430,20.7364,,0.082186544
24.11634362,45.135,415,20.3715,,0.079319572
24.19512531,45.135,449,21.1896,,0.085818043
24.27390701,45.135,388,19.6977,,0.074159021
24.3526887,45.135,467,21.6102,,0.08925841
24.4314704,45.135,395,19.8746,,0.075496942
24.5102521,45.135,395,19.8746,,0.075496942
24.58903379,45.135,381,19.5192,,0.072821101
24.66781549,45.135,353,18.7883,,0.067469419
24.74659718,45.135,388,19.6977,,0.074159021
24.82537888,45.135,415,20.3715,,0.079319572
24.90416058,45.135,408,20.199,,0.077981651
24.98294227,45.135,404,20.0998,,0.077217125
25.06172397,45.135,385,19.6214,,0.073585627
25.14050566,45.135,435,20.8567,,0.083142202
25.21928736,45.135,422,20.5426,,0.080657492
25.29806906,45.135,380,19.4936,,0.072629969
25.37685075,45.135,402,20.0499,,0.076834862
25.45563245,45.135,443,21.0476,,0.084671254
25.53441414,45.135,372,19.2873,,0.071100917
25.61319584,45.135,357,18.8944,,0.068233945
25.69197754,45.135,410,20.2485,,0.078363914
25.77075923,45.135,398,19.9499,,0.076070336
25.84954093,45.135,382,19.5448,,0.073012232
25.92832262,45.135,363,19.0526,,0.069380734
26.00710432,45.135,367,19.1572,,0.07014526
26.08588602,45.135,418,20.445,,0.079892966
26.16466771,45.135,412,20.2978,,0.078746177
26.24344941,45.135,377,19.4165,,0.072056575
26.32223111,45.135,381,19.5192,,0.072821101
26.4010128,45.135,376,19.3907,,0.071865443
26.4797945,45.135,371,19.2614,,0.070909786
26.55857619,45.135,367,19.1572,,0.07014526
26.63735789,45.135,373,19.3132,,0.071292049
26.71613959,45.135,392,19.799,,0.074923547
26.79492128,45.135,382,19.5448,,0.073012232
26.87370298,45.135,392,19.799,,0.074923547
26.95248467,45.135,415,20.3715,,0.079319572
27.03126637,45.135,422,20.5426,,0.080657492
27.11004807,45.135,398,19.9499,,0.076070336
27.18882976,45.135,367,19.1572,,0.07014526
27.26761146,45.135,374,19.3391,,0.07148318
27.34639315,45.135,408,20.199,,0.077981651
27.42517485,45.135,417,20.4206,,0.079701835
27.50395655,45.135,402,20.0499,,0.076834862
27.58273824,45.135,414,20.347,,0.07912844
27.66151994,45.135,431,20.7605,,0.082377676
27.74030163,45.135,463,21.5174,,0.088493884
27.81908333,45.135,521,22.8254,,0.099579511
27.89786503,45.135,600,24.4949,,0.114678899
27.97664672,45.135,670,25.8844,,0.128058104
28.05542842,45.135,627,25.04,,0.11983945
28.13421011,45.135,515,22.6936,,0.098432722
28.21299181,45.135,452,21.2603,,0.086391437
28.29177351,45.135,445,21.095,,0.085053517
28.3705552,45.135,408,20.199,,0.077981651
28.4493369,45.135,357,18.8944,,0.068233945
28.52811859,45.135,377,19.4165,,0.072056575
28.60690029,45.135,421,20.5183,,0.080466361
28.68568199,45.135,380,19.4936,,0.072629969
28.76446368,45.135,401,20.025,,0.076643731
28.84324538,45.135,399,19.975,,0.076261468
28.92202708,45.135,350,18.7083,,0.066896024
29.00080877,45.135,350,18.7083,,0.066896024
29.07959047,45.135,366,19.1311,,0.069954128
29.15837216,45.135,346,18.6011,,0.066131498
29.23715386,45.135,363,19.0526,,0.069380734
29.31593556,45.135,334,18.2757,,0.06383792
29.39471725,45.135,362,19.0263,,0.069189602
29.47349895,45.135,359,18.9473,,0.068616208
29.55228064,45.135,338,18.3848,,0.064602446
29.63106234,45.135,336,18.3303,,0.064220183
29.70984404,45.135,364,19.0788,,0.069571865
29.78862573,45.135,341,18.4662,,0.065175841
29.86740743,45.135,347,18.6279,,0.06632263
29.94618912,45.135,339,18.412,,0.064793578
30.02497082,45.135,390,19.7484,,0.074541284
30.10375252,45.135,366,19.1311,,0.069954128
30.18253421,45.135,374,19.3391,,0.07148318
30.26131591,45.135,341,18.4662,,0.065175841
30.3400976,45.135,340,18.4391,,0.064984709
30.4188793,45.135,360,18.9737,,0.068807339
30.497661,45.135,334,18.2757,,0.06383792
30.57644269,45.135,338,18.3848,,0.064602446
30.65522439,45.135,394,19.8494,,0.07530581
30.73400608,45.135,348,18.6548,,0.066513761
30.81278778,45.135,324,18,,0.061926606
30.89156948,45.135,340,18.4391,,0.064984709
30.97035117,45.135,338,18.3848,,0.064602446
31.04913287,45.135,358,18.9209,,0.068425076
31.12791456,45.135,361,19,,0.068998471
31.20669626,45.135,368,19.1833,,0.070336391
31.28547796,45.135,353,18.7883,,0.067469419
31.36425965,45.135,395,19.8746,,0.075496942
31.44304135,45.135,346,18.6011,,0.066131498
31.52182304,45.135,332,18.2209,,0.063455657
31.60060474,45.135,383,19.5704,,0.073203364
31.67938644,45.135,339,18.412,,0.064793578
31.75816813,45.135,352,18.7617,,0.067278287
31.83694983,45.135,361,19,,0.068998471
31.91573153,45.135,380,19.4936,,0.072629969
31.99451322,45.135,434,20.8327,,0.08295107
32.07329492,45.135,550,23.4521,,0.105122324
32.15207661,45.135,1026,32.0312,,0.196100917
32.23085831,45.135,1822,42.6849,,0.34824159
32.30964001,45.135,1432,37.8418,,0.273700306
32.3884217,45.135,777,27.8747,,0.148509174
32.4672034,45.135,456,21.3542,,0.087155963
32.54598509,45.135,372,19.2873,,0.071100917
32.62476679,45.135,412,20.2978,,0.078746177
32.70354849,45.135,378,19.4422,,0.072247706
32.78233018,45.135,375,19.3649,,0.071674312
32.86111188,45.135,357,18.8944,,0.068233945
32.93989357,45.135,338,18.3848,,0.064602446
33.01867527,45.135,371,19.2614,,0.070909786
33.09745697,45.135,346,18.6011,,0.066131498
33.17623866,45.135,367,19.1572,,0.07014526
33.25502036,45.135,369,19.2094,,0.070527523
33.33380205,45.135,347,18.6279,,0.06632263
33.41258375,45.135,317,17.8045,,0.060588685
33.49136545,45.135,324,18,,0.061926606
33.57014714,45.135,340,18.4391,,0.064984709
33.64892884,45.135,358,18.9209,,0.068425076
33.72771053,45.135,372,19.2873,,0.071100917
33.80649223,45.135,359,18.9473,,0.068616208
33.88527393,45.135,371,19.2614,,0.070909786
33.96405562,45.135,385,19.6214,,0.073585627
34.04283732,45.135,391,19.7737,,0.074732416
34.12161901,45.135,357,18.8944,,0.068233945
34.20040071,45.135,411,20.2731,,0.078555046
34.27918241,45.135,523,22.8692,,0.099961774
34.3579641,45.135,890,29.8329,,0.170107034
34.4367458,45.135,1652,40.6448,,0.315749235
34.5155275,45.135,1620,40.2492,,0.309633028
34.59430919,45.135,1008,31.749,,0.19266055
34.67309089,45.135,515,22.6936,,0.098432722
34.75187258,45.135,434,20.8327,,0.08295107
34.83065428,45.135,404,20.0998,,0.077217125
34.90943598,45.135,392,19.799,,0.074923547
34.98821767,45.135,350,18.7083,,0.066896024
35.06699937,45.135,364,19.0788,,0.069571865
35.14578106,45.135,374,19.3391,,0.07148318
35.22456276,45.135,363,19.0526,,0.069380734
35.30334446,45.135,394,19.8494,,0.07530581
35.38212615,45.135,388,19.6977,,0.074159021
35.46090785,45.135,402,20.0499,,0.076834862
35.53968954,45.135,477,21.8403,,0.091169725
35.61847124,45.135,529,23,,0.101108563
35.69725294,45.135,502,22.4054,,0.095948012
35.77603463,45.135,657,25.632,,0.125573394
35.85481633,45.135,630,25.0998,,0.120412844
35.93359802,45.135,518,22.7596,,0.099006116
36.01237972,45.135,484,22,,0.092507645
36.09116142,45.135,418,20.445,,0.079892966
36.16994311,45.135,419,20.4695,,0.080084098
36.24872481,45.135,450,21.2132,,0.086009174
36.3275065,45.135,491,22.1585,,0.093845566
36.4062882,45.135,721,26.8514,,0.13780581
36.4850699,45.135,1096,33.1059,,0.209480122
36.56385159,45.135,2211,47.0213,,0.422591743
36.64263329,45.135,4837,69.5485,,0.924503058
36.72141498,45.135,4875,69.8212,,0.931766055
36.80019668,45.135,2845,53.3385,,0.543769113
36.87897838,45.135,1218,34.8999,,0.232798165
36.95776007,45.135,623,24.96,,0.119074924
37.03654177,45.135,539,23.2164,,0.103019878
37.11532347,45.135,412,20.2978,,0.078746177
37.19410516,45.135,425,20.6155,,0.081230887
37.27288686,45.135,393,19.8242,,0.075114679
37.35166855,45.135,399,19.975,,0.076261468
37.43045025,45.135,360,18.9737,,0.068807339
37.50923195,45.135,355,18.8414,,0.067851682
37.58801364,45.135,373,19.3132,,0.071292049
37.66679534,45.135,340,18.4391,,0.064984709
37.74557703,45.135,368,19.1833,,0.070336391
37.82435873,45.135,344,18.5472,,0.065749235
37.90314043,45.135,333,18.2483,,0.063646789
37.98192212,45.135,353,18.7883,,0.067469419
38.06070382,45.135,358,18.9209,,0.068425076
38.13948551,45.135,345,18.5742,,0.065940367
38.21826721,45.135,320,17.8885,,0.06116208
38.29704891,45.135,324,18,,0.061926606
38.3758306,45.135,315,17.7482,,0.060206422
38.4546123,45.135,316,17.7764,,0.060397554
38.53339399,45.135,353,18.7883,,0.067469419
38.61217569,45.135,348,18.6548,,0.066513761
38.69095739,45.135,318,17.8326,,0.060779817
38.76973908,45.135,335,18.303,,0.064029052
38.84852078,45.135,302,17.3781,,0.057721713
38.92730247,45.135,298,17.2627,,0.056957187
39.00608417,45.135,332,18.2209,,0.063455657
39.08486587,45.135,369,19.2094,,0.070527523
39.16364756,45.135,322,17.9444,,0.061544343
39.24242926,45.135,348,18.6548,,0.066513761
39.32121095,45.135,307,17.5214,,0.05867737
39.39999265,45.135,302,17.3781,,0.057721713
39.47877435,45.135,332,18.2209,,0.063455657
39.55755604,45.135,316,17.7764,,0.060397554
39.63633774,45.135,320,17.8885,,0.06116208
39.71511943,45.135,325,18.0278,,0.062117737
39.79390113,45.135,324,18,,0.061926606
39.87268283,45.135,405,20.1246,,0.077408257
39.95146452,45.135,370,19.2354,,0.070718654
40.03024622,45.135,396,19.8997,,0.075688073
40.10902792,45.135,325,18.0278,,0.062117737
40.18780961,45.135,366,19.1311,,0.069954128
40.26659131,45.135,319,17.8606,,0.060970948
40.345373,45.135,352,18.7617,,0.067278287
40.4241547,45.135,333,18.2483,,0.063646789
40.5029364,45.135,328,18.1108,,0.062691131
40.58171809,45.135,285,16.8819,,0.054472477
40.66049979,45.135,355,18.8414,,0.067851682
40.73928148,45.135,324,18,,0.061926606
40.81806318,45.135,311,17.6352,,0.059441896
40.89684488,45.135,337,18.3576,,0.064411315
40.97562657,45.135,290,17.0294,,0.055428135
41.05440827,45.135,292,17.088,,0.055810398
41.13318996,45.135,281,16.7631,,0.053707951
41.21197166,45.135,303,17.4069,,0.057912844
41.29075336,45.135,336,18.3303,,0.064220183
41.36953505,45.135,310,17.6068,,0.059250765
41.44831675,45.135,291,17.0587,,0.055619266
41.52709844,45.135,357,18.8944,,0.068233945
41.60588014,45.135,320,17.8885,,0.06116208
41.68466184,45.135,312,17.6635,,0.059633028
41.76344353,45.135,320,17.8885,,0.06116208
41.84222523,45.135,288,16.9706,,0.055045872
41.92100692,45.135,311,17.6352,,0.059441896
41.99978862,45.135,298,17.2627,,0.056957187
42.07857032,45.135,278,16.6733,,0.053134557
42.15735201,45.135,327,18.0831,,0.0625
42.23613371,45.135,305,17.4642,,0.058295107
42.3149154,45.135,295,17.1756,,0.056383792
42.3936971,45.135,296,17.2047,,0.056574924
42.4724788,45.135,285,16.8819,,0.054472477
42.55126049,45.135,319,17.8606,,0.060970948
42.63004219,45.135,312,17.6635,,0.059633028
42.70882389,45.135,324,18,,0.061926606
42.78760558,45.135,330,18.1659,,0.063073394
42.86638728,45.135,340,18.4391,,0.064984709
42.94516897,45.135,329,18.1384,,0.062882263
43.02395067,45.135,321,17.9165,,0.061353211
43.10273237,45.135,284,16.8523,,0.054281346
43.18151406,45.135,324,18,,0.061926606
43.26029576,45.135,296,17.2047,,0.056574924
43.33907745,45.135,336,18.3303,,0.064220183
43.41785915,45.135,293,17.1172,,0.056001529
43.49664085,45.135,332,18.2209,,0.063455657
43.57542254,45.135,323,17.9722,,0.061735474
43.65420424,45.135,289,17,,0.055237003
43.73298593,45.135,290,17.0294,,0.055428135
43.81176763,45.135,310,17.6068,,0.059250765
43.89054933,45.135,299,17.2916,,0.057148318
43.96933102,45.135,318,17.8326,,0.060779817
44.04811272,45.135,291,17.0587,,0.055619266
44.12689441,45.135,251,15.843,,0.047974006
44.20567611,45.135,326,18.0555,,0.062308869
44.28445781,45.135,306,17.4929,,0.058486239
44.3632395,45.135,281,16.7631,,0.053707951
44.4420212,45.135,287,16.9411,,0.05485474
44.52080289,45.135,323,17.9722,,0.061735474
44.59958459,45.135,292,17.088,,0.055810398
44.67836629,45.135,263,16.2173,,0.050267584
44.75714798,45.135,297,17.2337,,0.056766055
44.83592968,45.135,256,16,,0.048929664
44.91471137,45.135,266,16.3095,,0.050840979
44.99349307,45.135,308,17.5499,,0.058868502
45.07227477,45.135,290,17.0294,,0.055428135
45.15105646,45.135,300,17.3205,,0.05733945
45.22983816,45.135,293,17.1172,,0.056001529
45.30861986,45.135,301,17.3494,,0.057530581
45.38740155,45.135,315,17.7482,,0.060206422
45.46618325,45.135,272,16.4924,,0.051987768
45.54496494,45.135,281,16.7631,,0.053707951
45.62374664,45.135,292,17.088,,0.055810398
45.70252834,45.135,299,17.2916,,0.057148318
45.78131003,45.135,315,17.7482,,0.060206422
45.86009173,45.135,307,17.5214,,0.05867737
45.93887342,45.135,337,18.3576,,0.064411315
46.01765512,45.135,310,17.6068,,0.059250765
46.09643682,45.135,297,17.2337,,0.056766055
46.17521851,45.135,295,17.1756,,0.056383792
46.25400021,45.135,289,17,,0.055237003
46.3327819,45.135,279,16.7033,,0.053325688
46.4115636,45.135,288,16.9706,,0.055045872
46.4903453,45.135,260,16.1245,,0.04969419
46.56912699,45.135,304,17.4356,,0.058103976
46.64790869,45.135,265,16.2788,,0.050649847
46.72669038,45.135,282,16.7929,,0.053899083
46.80547208,45.135,321,17.9165,,0.061353211
46.88425378,45.135,289,17,,0.055237003
46.96303547,45.135,260,16.1245,,0.04969419
47.04181717,45.135,290,17.0294,,0.055428135
47.12059886,45.135,277,16.6433,,0.052943425
47.19938056,45.135,291,17.0587,,0.055619266
47.27816226,45.135,333,18.2483,,0.063646789
47.35694395,45.135,297,17.2337,,0.056766055
47.43572565,45.135,281,16.7631,,0.053707951
47.51450734,45.135,284,16.8523,,0.054281346
47.59328904,45.135,355,18.8414,,0.067851682
47.67207074,45.135,359,18.9473,,0.068616208
47.75085243,45.135,492,22.1811,,0.094036697
47.82963413,45.135,682,26.1151,,0.130351682
47.90841582,45.135,819,28.6182,,0.156536697
47.98719752,45.135,655,25.593,,0.125191131
48.06597922,45.135,507,22.5167,,0.09690367
48.14476091,45.135,349,18.6815,,0.066704893
48.22354261,45.135,329,18.1384,,0.062882263
48.30232431,45.135,310,17.6068,,0.059250765
48.381106,45.135,326,18.0555,,0.062308869
48.4598877,45.135,298,17.2627,,0.056957187
48.53866939,45.135,324,18,,0.061926606
48.61745109,45.135,241,15.5242,,0.046062691
48.69623279,45.135,283,16.8226,,0.054090214
48.77501448,45.135,291,17.0587,,0.055619266
48.85379618,45.135,273,16.5227,,0.052178899
48.93257787,45.135,283,16.8226,,0.054090214
49.01135957,45.135,295,17.1756,,0.056383792
49.09014127,45.135,276,16.6132,,0.052752294
49.16892296,45.135,238,15.4272,,0.045489297
49.24770466,45.135,271,16.4621,,0.051796636
49.32648635,45.135,295,17.1756,,0.056383792
49.40526805,45.135,262,16.1864,,0.050076453
49.48404975,45.135,310,17.6068,,0.059250765
49.56283144,45.135,294,17.1464,,0.056192661
49.64161314,45.135,264,16.2481,,0.050458716
49.72039483,45.135,262,16.1864,,0.050076453
49.79917653,45.135,294,17.1464,,0.056192661
49.87795823,45.135,284,16.8523,,0.054281346
49.95673992,45.135,261,16.1555,,0.049885321
50.03552162,45.135,294,17.1464,,0.056192661
50.11430331,45.135,276,16.6132,,0.052752294
50.19308501,45.135,268,16.3707,,0.051223242
50.27186671,45.135,278,16.6733,,0.053134557
50.3506484,45.135,281,16.7631,,0.053707951
50.4294301,45.135,297,17.2337,,0.056766055
50.50821179,45.135,285,16.8819,,0.054472477
50.58699349,45.135,252,15.8745,,0.048165138
50.66577519,45.135,280,16.7332,,0.05351682
50.74455688,45.135,281,16.7631,,0.053707951
50.82333858,45.135,271,16.4621,,0.051796636
50.90212028,45.135,275,16.5831,,0.052561162
50.98090197,45.135,293,17.1172,,0.056001529
51.05968367,45.135,288,16.9706,,0.055045872
51.13846536,45.135,276,16.6132,,0.052752294
51.21724706,45.135,278,16.6733,,0.053134557
51.29602876,45.135,265,16.2788,,0.050649847
51.37481045,45.135,248,15.748,,0.047400612
51.45359215,45.135,280,16.7332,,0.05351682
51.53237384,45.135,259,16.0935,,0.049503058
51.61115554,45.135,248,15.748,,0.047400612
51.68993724,45.135,263,16.2173,,0.050267584
51.76871893,45.135,263,16.2173,,0.050267584
51.84750063,45.135,275,16.5831,,0.052561162
51.92628232,45.135,267,16.3401,,0.05103211
52.00506402,45.135,262,16.1864,,0.050076453
52.08384572,45.135,287,16.9411,,0.05485474
52.16262741,45.135,263,16.2173,,0.050267584
52.24140911,45.135,246,15.6844,,0.047018349
52.3201908,45.135,265,16.2788,,0.050649847
52.3989725,45.135,266,16.3095,,0.050840979
52.4777542,45.135,241,15.5242,,0.046062691
52.55653589,45.135,242,15.5563,,0.046253823
52.63531759,45.135,270,16.4317,,0.051605505
52.71409928,45.135,238,15.4272,,0.045489297
52.79288098,45.135,249,15.7797,,0.047591743
52.87166268,45.135,241,15.5242,,0.046062691
52.95044437,45.135,283,16.8226,,0.054090214
53.02922607,45.135,263,16.2173,,0.050267584
53.10800776,45.135,269,16.4012,,0.051414373
53.18678946,45.135,227,15.0665,,0.04338685
53.26557116,45.135,267,16.3401,,0.05103211
53.34435285,45.135,253,15.906,,0.048356269
53.42313455,45.135,287,16.9411,,0.05485474
53.50191625,45.135,259,16.0935,,0.049503058
53.58069794,45.135,278,16.6733,,0.053134557
53.65947964,45.135,245,15.6525,,0.046827217
53.73826133,45.135,262,16.1864,,0.050076453
53.81704303,45.135,244,15.6205,,0.046636086
53.89582473,45.135,271,16.4621,,0.051796636
53.97460642,45.135,244,15.6205,,0.046636086
54.05338812,45.135,235,15.3297,,0.044915902
54.13216981,45.135,289,17,,0.055237003
54.21095151,45.135,272,16.4924,,0.051987768
54.28973321,45.135,247,15.7162,,0.04720948
54.3685149,45.135,257,16.0312,,0.049120795
54.4472966,45.135,287,16.9411,,0.05485474
54.52607829,45.135,322,17.9444,,0.061544343
54.60485999,45.135,349,18.6815,,0.066704893
54.68364169,45.135,350,18.7083,,0.066896024
54.76242338,45.135,339,18.412,,0.064793578
54.84120508,45.135,370,19.2354,,0.070718654
54.91998677,45.135,326,18.0555,,0.062308869
54.99876847,45.135,253,15.906,,0.048356269
55.07755017,45.135,266,16.3095,,0.050840979
55.15633186,45.135,269,16.4012,,0.051414373
55.23511356,45.135,251,15.843,,0.047974006
55.31389525,45.135,249,15.7797,,0.047591743
55.39267695,45.135,269,16.4012,,0.051414373
55.47145865,45.135,260,16.1245,,0.04969419
55.55024034,45.135,265,16.2788,,0.050649847
55.62902204,45.135,234,15.2971,,0.044724771
55.70780373,45.135,246,15.6844,,0.047018349
55.78658543,45.135,227,15.0665,,0.04338685
55.86536713,45.135,241,15.5242,,0.046062691
55.94414882,45.135,265,16.2788,,0.050649847
56.02293052,45.135,255,15.9687,,0.048738532
56.10171221,45.135,262,16.1864,,0.050076453
56.18049391,45.135,259,16.0935,,0.049503058
56.25927561,45.135,230,15.1658,,0.043960245
56.3380573,45.135,269,16.4012,,0.051414373
56.416839,45.135,253,15.906,,0.048356269
56.4956207,45.135,228,15.0997,,0.043577982
56.57440239,45.135,236,15.3623,,0.045107034
56.65318409,45.135,300,17.3205,,0.05733945
56.73196578,45.135,224,14.9666,,0.042813456
56.81074748,45.135,255,15.9687,,0.048738532
56.88952918,45.135,233,15.2643,,0.044533639
56.96831087,45.135,275,16.5831,,0.052561162
57.04709257,45.135,236,15.3623,,0.045107034
57.12587426,45.135,276,16.6132,,0.052752294
57.20465596,45.135,282,16.7929,,0.053899083
57.28343766,45.135,364,19.0788,,0.069571865
57.36221935,45.135,641,25.318,,0.122515291
57.44100105,45.135,814,28.5307,,0.15558104
57.51978274,45.135,619,24.8797,,0.118310398
57.59856444,45.135,537,23.1733,,0.102637615
57.67734614,45.135,371,19.2614,,0.070909786
57.75612783,45.135,269,16.4012,,0.051414373
57.83490953,45.135,259,16.0935,,0.049503058
57.91369122,45.135,258,16.0624,,0.049311927
57.99247292,45.135,272,16.4924,,0.051987768
58.07125462,45.135,222,14.8997,,0.042431193
58.15003631,45.135,242,15.5563,,0.046253823
58.22881801,45.135,221,14.8661,,0.042240061
58.3075997,45.135,225,15,,0.043004587
58.3863814,45.135,248,15.748,,0.047400612
58.4651631,45.135,237,15.3948,,0.045298165
58.54394479,45.135,265,16.2788,,0.050649847
58.62272649,45.135,203,14.2478,,0.038799694
58.70150818,45.135,216,14.6969,,0.041284404
58.78028988,45.135,229,15.1327,,0.043769113
58.85907158,45.135,213,14.5945,,0.040711009
58.93785327,45.135,235,15.3297,,0.044915902
59.01663497,45.135,208,14.4222,,0.039755352
59.09541667,45.135,220,14.8324,,0.04204893
59.17419836,45.135,205,14.3178,,0.039181957
59.25298006,45.135,231,15.1987,,0.044151376
59.33176175,45.135,198,14.0712,,0.037844037
59.41054345,45.135,215,14.6629,,0.041093272
59.48932515,45.135,204,14.2829,,0.038990826
59.56810684,45.135,238,15.4272,,0.045489297
59.64688854,45.135,224,14.9666,,0.042813456
59.72567023,45.135,210,14.4914,,0.040137615
59.80445193,45.135,234,15.2971,,0.044724771
59.88323363,45.135,211,14.5258,,0.040328746
59.96201532,45.135,198,14.0712,,0.037844037
60.04079702,45.135,231,15.1987,,0.044151376
60.11957871,45.135,221,14.8661,,0.042240061
60.19836041,45.135,237,15.3948,,0.045298165
60.27714211,45.135,223,14.9332,,0.042622324
60.3559238,45.135,250,15.8114,,0.047782875
60.4347055,45.135,222,14.8997,,0.042431193
60.51348719,45.135,215,14.6629,,0.041093272
60.59226889,45.135,234,15.2971,,0.044724771
60.67105059,45.135,193,13.8924,,0.036888379
60.74983228,45.135,250,15.8114,,0.047782875
60.82861398,45.135,243,15.5885,,0.046444954
60.90739567,45.135,209,14.4568,,0.039946483
60.98617737,45.135,246,15.6844,,0.047018349
61.06495907,45.135,235,15.3297,,0.044915902
61.14374076,45.135,244,15.6205,,0.046636086
61.22252246,45.135,255,15.9687,,0.048738532
61.30130415,45.135,194,13.9284,,0.037079511
61.38008585,45.135,236,15.3623,,0.045107034
61.45886755,45.135,211,14.5258,,0.040328746
61.53764924,45.135,221,14.8661,,0.042240061
61.61643094,45.135,245,15.6525,,0.046827217
61.69521264,45.135,202,14.2127,,0.038608563
61.77399433,45.135,221,14.8661,,0.042240061
61.85277603,45.135,195,13.9642,,0.037270642
61.93155772,45.135,229,15.1327,,0.043769113
62.01033942,45.135,230,15.1658,,0.043960245
62.08912112,45.135,216,14.6969,,0.041284404
62.16790281,45.135,223,14.9332,,0.042622324
62.24668451,45.135,228,15.0997,,0.043577982
62.3254662,45.135,229,15.1327,,0.043769113
62.4042479,45.135,260,16.1245,,0.04969419
62.4830296,45.135,232,15.2315,,0.044342508
62.56181129,45.135,236,15.3623,,0.045107034
62.64059299,45.135,224,14.9666,,0.042813456
62.71937468,45.135,255,15.9687,,0.048738532
62.79815638,45.135,266,16.3095,,0.050840979
62.87693808,45.135,244,15.6205,,0.046636086
62.95571977,45.135,336,18.3303,,0.064220183
63.03450147,45.135,439,20.9523,,0.083906728
63.11328316,45.135,628,25.0599,,0.120030581
63.19206486,45.135,540,23.2379,,0.103211009
63.27084656,45.135,520,22.8035,,0.099388379
63.34962825,45.135,407,20.1742,,0.07779052
63.42840995,45.135,273,16.5227,,0.052178899
63.50719164,45.135,237,15.3948,,0.045298165
63.58597334,45.135,227,15.0665,,0.04338685
63.66475504,45.135,212,14.5602,,0.040519878
63.74353673,45.135,200,14.1421,,0.0382263
63.82231843,45.135,201,14.1774,,0.038417431
63.90110012,45.135,232,15.2315,,0.044342508
63.97988182,45.135,217,14.7309,,0.041475535
64.05866352,45.135,193,13.8924,,0.036888379
64.13744521,45.135,210,14.4914,,0.040137615
64.21622691,45.135,190,13.784,,0.036314985
64.2950086,45.135,210,14.4914,,0.040137615
64.3737903,45.135,198,14.0712,,0.037844037
64.452572,45.135,220,14.8324,,0.04204893
64.53135369,45.135,228,15.0997,,0.043577982
64.61013539,45.135,175,13.2288,,0.033448012
64.68891709,45.135,216,14.6969,,0.041284404
64.76769878,45.135,173,13.1529,,0.033065749
64.84648048,45.135,212,14.5602,,0.040519878
64.92526217,45.135,210,14.4914,,0.040137615
65.00404387,45.135,210,14.4914,,0.040137615
65.08282557,45.135,177,13.3041,,0.033830275
65.16160726,45.135,220,14.8324,,0.04204893
65.24038896,45.135,230,15.1658,,0.043960245
65.31917065,45.135,248,15.748,,0.047400612
65.39795235,45.135,219,14.7986,,0.041857798
65.47673405,45.135,200,14.1421,,0.0382263
65.55551574,45.135,211,14.5258,,0.040328746
65.63429744,45.135,219,14.7986,,0.041857798
65.71307913,45.135,208,14.4222,,0.039755352
65.79186083,45.135,179,13.3791,,0.034212538
65.87064253,45.135,228,15.0997,,0.043577982
65.94942422,45.135,221,14.8661,,0.042240061
66.02820592,45.135,174,13.1909,,0.033256881
66.10698761,45.135,193,13.8924,,0.036888379
66.18576931,45.135,202,14.2127,,0.038608563
66.26455101,45.135,194,13.9284,,0.037079511
66.3433327,45.135,192,13.8564,,0.036697248
66.4221144,45.135,205,14.3178,,0.039181957
66.50089609,45.135,183,13.5277,,0.034977064
66.57967779,45.135,181,13.4536,,0.034594801
66.65845949,45.135,195,13.9642,,0.037270642
66.73724118,45.135,193,13.8924,,0.036888379
66.81602288,45.135,201,14.1774,,0.038417431
66.89480457,45.135,230,15.1658,,0.043960245
66.97358627,45.135,194,13.9284,,0.037079511
67.05236797,45.135,223,14.9332,,0.042622324
67.13114966,45.135,214,14.6287,,0.040902141
67.20993136,45.135,193,13.8924,,0.036888379
67.28871306,45.135,223,14.9332,,0.042622324
67.36749475,45.135,258,16.0624,,0.049311927
67.44627645,45.135,226,15.0333,,0.043195719
67.52505814,45.135,246,15.6844,,0.047018349
67.60383984,45.135,227,15.0665,,0.04338685
67.68262154,45.135,180,13.4164,,0.03440367
67.76140323,45.135,207,14.3875,,0.03956422
67.84018493,45.135,228,15.0997,,0.043577982
67.91896662,45.135,220,14.8324,,0.04204893
67.99774832,45.135,205,14.3178,,0.039181957
68.07653002,45.135,212,14.5602,,0.040519878
68.15531171,45.135,189,13.7477,,0.036123853
68.23409341,45.135,232,15.2315,,0.044342508
68.3128751,45.135,186,13.6382,,0.035550459
68.3916568,45.135,248,15.748,,0.047400612
68.4704385,45.135,266,16.3095,,0.050840979
68.54922019,45.135,333,18.2483,,0.063646789
68.62800189,45.135,529,23,,0.101108563
68.70678358,45.135,580,24.0832,,0.110856269
68.78556528,45.135,445,21.095,,0.085053517
68.86434698,45.135,475,21.7945,,0.090787462
68.94312867,45.135,346,18.6011,,0.066131498
69.02191037,45.135,258,16.0624,,0.049311927
69.10069206,45.135,211,14.5258,,0.040328746
69.17947376,45.135,204,14.2829,,0.038990826
69.25825546,45.135,209,14.4568,,0.039946483
69.33703715,45.135,178,13.3417,,0.034021407
69.41581885,45.135,184,13.5647,,0.035168196
69.49460054,45.135,220,14.8324,,0.04204893
69.57338224,45.135,197,14.0357,,0.037652905
69.65216394,45.135,221,14.8661,,0.042240061
69.73094563,45.135,233,15.2643,,0.044533639
69.80972733,45.135,210,14.4914,,0.040137615
69.88850903,45.135,300,17.3205,,0.05733945
69.96729072,45.135,376,19.3907,,0.071865443
70.04607242,45.135,469,21.6564,,0.089640673
70.12485411,45.135,402,20.0499,,0.076834862
70.20363581,45.135,367,19.1572,,0.07014526
70.28241751,45.135,285,16.8819,,0.054472477
70.3611992,45.135,246,15.6844,,0.047018349
70.4399809,45.135,226,15.0333,,0.043195719
70.51876259,45.135,210,14.4914,,0.040137615
70.59754429,45.135,203,14.2478,,0.038799694
70.67632599,45.135,192,13.8564,,0.036697248
70.75510768,45.135,189,13.7477,,0.036123853
70.83388938,45.135,189,13.7477,,0.036123853
70.91267107,45.135,182,13.4907,,0.034785933
70.99145277,45.135,200,14.1421,,0.0382263
71.07023447,45.135,189,13.7477,,0.036123853
71.14901616,45.135,176,13.2665,,0.033639144
71.22779786,45.135,213,14.5945,,0.040711009
71.30657955,45.135,190,13.784,,0.036314985
71.38536125,45.135,174,13.1909,,0.033256881
71.46414295,45.135,191,13.8203,,0.036506116
71.54292464,45.135,187,13.6748,,0.03574159
71.62170634,45.135,182,13.4907,,0.034785933
71.70048803,45.135,154,12.4097,,0.029434251
71.77926973,45.135,177,13.3041,,0.033830275
71.85805143,45.135,190,13.784,,0.036314985
71.93683312,45.135,185,13.6015,,0.035359327
72.01561482,45.135,184,13.5647,,0.035168196
72.09439651,45.135,153,12.3693,,0.029243119
72.17317821,45.135,192,13.8564,,0.036697248
72.25195991,45.135,206,14.3527,,0.039373089
72.3307416,45.135,188,13.7113,,0.035932722
72.4095233,45.135,190,13.784,,0.036314985
72.488305,45.135,209,14.4568,,0.039946483
72.56708669,45.135,224,14.9666,,0.042813456
72.64586839,45.135,219,14.7986,,0.041857798
72.72465008,45.135,226,15.0333,,0.043195719
72.80343178,45.135,232,15.2315,,0.044342508
72.88221348,45.135,207,14.3875,,0.03956422
72.96099517,45.135,152,12.3288,,0.029051988
73.03977687,45.135,167,12.9228,,0.03191896
73.11855856,45.135,165,12.8452,,0.031536697
73.19734026,45.135,162,12.7279,,0.030963303
73.27612196,45.135,161,12.6886,,0.030772171
73.35490365,45.135,170,13.0384,,0.032492355
73.43368535,45.135,188,13.7113,,0.035932722
73.51246704,45.135,165,12.8452,,0.031536697
73.59124874,45.135,167,12.9228,,0.03191896
73.67003044,45.135,168,12.9615,,0.032110092
73.74881213,45.135,179,13.3791,,0.034212538
73.82759383,45.135,185,13.6015,,0.035359327
73.90637552,45.135,171,13.0767,,0.032683486
73.98515722,45.135,178,13.3417,,0.034021407
74.06393892,45.135,158,12.5698,,0.030198777
74.14272061,45.135,190,13.784,,0.036314985
74.22150231,45.135,158,12.5698,,0.030198777
74.300284,45.135,156,12.49,,0.029816514
74.3790657,45.135,181,13.4536,,0.034594801
74.4578474,45.135,169,13,,0.032301223
74.53662909,45.135,182,13.4907,,0.034785933
74.61541079,45.135,147,12.1244,,0.02809633
74.69419248,45.135,156,12.49,,0.029816514
74.77297418,45.135,160,12.6491,,0.03058104
74.85175588,45.135,147,12.1244,,0.02809633
74.93053757,45.135,146,12.083,,0.027905199
75.00931927,45.135,174,13.1909,,0.033256881
75.08810096,45.135,186,13.6382,,0.035550459
75.16688266,45.135,164,12.8062,,0.031345566
75.24566436,45.135,144,12,,0.027522936
75.32444605,45.135,170,13.0384,,0.032492355
75.40322775,45.135,170,13.0384,,0.032492355
75.48200945,45.135,172,13.1149,,0.032874618
75.56079114,45.135,183,13.5277,,0.034977064
75.63957284,45.135,180,13.4164,,0.03440367
75.71835453,45.135,178,13.3417,,0.034021407
75.79713623,45.135,198,14.0712,,0.037844037
75.87591793,45.135,164,12.8062,,0.031345566
75.95469962,45.135,198,14.0712,,0.037844037
76.03348132,45.135,163,12.7671,,0.031154434
76.11226301,45.135,155,12.4499,,0.029625382
76.19104471,45.135,154,12.4097,,0.029434251
76.26982641,45.135,179,13.3791,,0.034212538
76.3486081,45.135,192,13.8564,,0.036697248
76.4273898,45.135,172,13.1149,,0.032874618
76.50617149,45.135,214,14.6287,,0.040902141
76.58495319,45.135,191,13.8203,,0.036506116
76.66373489,45.135,162,12.7279,,0.030963303
76.74251658,45.135,172,13.1149,,0.032874618
76.82129828,45.135,215,14.6629,,0.041093272
76.90007997,45.135,180,13.4164,,0.03440367
76.97886167,45.135,163,12.7671,,0.031154434
77.05764337,45.135,147,12.1244,,0.02809633
77.13642506,45.135,157,12.53,,0.030007645
77.21520676,45.135,175,13.2288,,0.033448012
77.29398845,45.135,177,13.3041,,0.033830275
77.37277015,45.135,176,13.2665,,0.033639144
77.45155185,45.135,145,12.0416,,0.027714067
77.53033354,45.135,179,13.3791,,0.034212538
77.60911524,45.135,160,12.6491,,0.03058104
77.68789693,45.135,162,12.7279,,0.030963303
77.76667863,45.135,173,13.1529,,0.033065749
77.84546033,45.135,196,14,,0.037461774
77.92424202,45.135,186,13.6382,,0.035550459
78.00302372,45.135,172,13.1149,,0.032874618
78.08180542,45.135,174,13.1909,,0.033256881
78.16058711,45.135,187,13.6748,,0.03574159
78.23936881,45.135,175,13.2288,,0.033448012
78.3181505,45.135,156,12.49,,0.029816514
78.3969322,45.135,167,12.9228,,0.03191896
78.4757139,45.135,172,13.1149,,0.032874618
78.55449559,45.135,164,12.8062,,0.031345566
78.63327729,45.135,158,12.5698,,0.030198777
78.71205898,45.135,159,12.6095,,0.030389908
78.79084068,45.135,158,12.5698,,0.030198777
78.86962238,45.135,163,12.7671,,0.031154434
78.94840407,45.135,164,12.8062,,0.031345566
79.02718577,45.135,136,11.6619,,0.025993884
79.10596746,45.135,160,12.6491,,0.03058104
79.18474916,45.135,170,13.0384,,0.032492355
79.26353086,45.135,159,12.6095,,0.030389908
79.34231255,45.135,167,12.9228,,0.03191896
79.42109425,45.135,136,11.6619,,0.025993884
79.49987594,45.135,154,12.4097,,0.029434251
79.57865764,45.135,156,12.49,,0.029816514
79.65743934,45.135,145,12.0416,,0.027714067
79.73622103,45.135,158,12.5698,,0.030198777
79.81500273,45.135,177,13.3041,,0.033830275
79.89378442,45.135,155,12.4499,,0.029625382
79.97256612,45.135,159,12.6095,,0.030389908