File: sheets/40W.csv
[Measurement conditions],,,,,
Sample identification,,,,,
Comment - 1,"Configuration=Reflection-transmission spinner, Owner=User-1, Creation date=12/4/2012 10:13:13 AM",,,,
Comment - 2,Goniometer=Theta/Theta; Minimum step size 2Theta:0.0001; Minimum step size Omega:0.0001,,,,
Comment - 3,Sample stage=Reflection-transmission spinner; Minimum step size Phi:0.1,,,,
Comment - 4,Diffractometer system=EMPYREAN,,,,
Comment - 5,"Measurement program=C:\PANalytical\Data Collector\Programs\PI Lorenzo Mangolini\BrandonWagner_Mg.xrdmp, Identifier={9EE36770-7A59-4EAA-85D0-90E43AFBFC91}",,,,
Anode material,Cu,,,,
K-Alpha1 wavelength,1.540598,,,,
K-Alpha2 wavelength,1.544426,,,,
Ratio K-Alpha2/K-Alpha1,0.5,,,,
Divergence slit,Fixed,0.76mm,,,
Monochromator used,NO,,,,
Generator voltage,45,,,,
Tube current,40,,,,
File date and time,4/5/2023 15:38,,,,
Unit cell,,,,,
h k l, 0 0 0,,,,
Scan axis,Gonio,,,,
Scan range,20,79.99226154,,,
Scan step size,0.0393908,,,,
No. of points,1523,,,,
Scan type,CONTINUOUS,,,,
Phi,338.7,,,,
Time per step,45.135,,,,
[Scan points],,,,,
Angle, TimePerStep, Intensity, ESD,,
20.01969542,45.135,512,22.6274,9263,0.055273669
20.09847712,45.135,479,21.8861,,0.051711109
20.17725881,45.135,481,21.9317,,0.051927021
20.25604051,45.135,509,22.561,,0.0549498
20.3348222,45.135,497,22.2935,,0.053654324
20.4136039,45.135,467,21.6102,,0.050415632
20.4923856,45.135,479,21.8861,,0.051711109
20.57116729,45.135,483,21.9773,,0.052142934
20.64994899,45.135,493,22.2036,,0.053222498
20.72873069,45.135,495,22.2486,,0.053438411
20.80751238,45.135,544,23.3238,,0.058728274
20.88629408,45.135,492,22.1811,,0.053114542
20.96507577,45.135,489,22.1133,,0.052790673
21.04385747,45.135,488,22.0907,,0.052682716
21.12263917,45.135,504,22.4499,,0.054410018
21.20142086,45.135,519,22.7816,,0.056029364
21.28020256,45.135,472,21.7256,,0.050955414
21.35898425,45.135,458,21.4009,,0.049444025
21.43776595,45.135,483,21.9773,,0.052142934
21.51654765,45.135,470,21.6795,,0.050739501
21.59532934,45.135,475,21.7945,,0.051279283
21.67411104,45.135,491,22.1585,,0.053006585
21.75289273,45.135,436,20.8806,,0.047068984
21.83167443,45.135,461,21.4709,,0.049767894
21.91045613,45.135,478,21.8632,,0.051603152
21.98923782,45.135,442,21.0238,,0.047716722
22.06801952,45.135,448,21.166,,0.048364461
22.14680121,45.135,511,22.6053,,0.055165713
22.22558291,45.135,469,21.6564,,0.050631545
22.30436461,45.135,467,21.6102,,0.050415632
22.3831463,45.135,468,21.6333,,0.050523588
22.461928,45.135,481,21.9317,,0.051927021
22.54070969,45.135,420,20.4939,,0.045341682
22.61949139,45.135,475,21.7945,,0.051279283
22.69827309,45.135,459,21.4243,,0.049551981
22.77705478,45.135,411,20.2731,,0.044370074
22.85583648,45.135,488,22.0907,,0.052682716
22.93461817,45.135,439,20.9523,,0.047392853
23.01339987,45.135,443,21.0476,,0.047824679
23.09218157,45.135,485,22.0227,,0.052358847
23.17096326,45.135,419,20.4695,,0.045233726
23.24974496,45.135,440,20.9762,,0.04750081
23.32852665,45.135,460,21.4476,,0.049659937
23.40730835,45.135,414,20.347,,0.044693944
23.48609005,45.135,441,21,,0.047608766
23.56487174,45.135,421,20.5183,,0.045449638
23.64365344,45.135,470,21.6795,,0.050739501
23.72243514,45.135,415,20.3715,,0.0448019
23.80121683,45.135,442,21.0238,,0.047716722
23.87999853,45.135,466,21.587,,0.050307676
23.95878022,45.135,420,20.4939,,0.045341682
24.03756192,45.135,438,20.9284,,0.047284897
24.11634362,45.135,429,20.7123,,0.046313289
24.19512531,45.135,419,20.4695,,0.045233726
24.27390701,45.135,412,20.2978,,0.044478031
24.3526887,45.135,428,20.6882,,0.046205333
24.4314704,45.135,426,20.6398,,0.04598942
24.5102521,45.135,455,21.3307,,0.049120155
24.58903379,45.135,409,20.2237,,0.044154162
24.66781549,45.135,458,21.4009,,0.049444025
24.74659718,45.135,422,20.5426,,0.045557595
24.82537888,45.135,432,20.7846,,0.046637159
24.90416058,45.135,434,20.8327,,0.046853071
24.98294227,45.135,435,20.8567,,0.046961028
25.06172397,45.135,438,20.9284,,0.047284897
25.14050566,45.135,393,19.8242,,0.04242686
25.21928736,45.135,449,21.1896,,0.048472417
25.29806906,45.135,409,20.2237,,0.044154162
25.37685075,45.135,413,20.3224,,0.044585987
25.45563245,45.135,412,20.2978,,0.044478031
25.53441414,45.135,425,20.6155,,0.045881464
25.61319584,45.135,410,20.2485,,0.044262118
25.69197754,45.135,372,19.2873,,0.040159775
25.77075923,45.135,391,19.7737,,0.042210947
25.84954093,45.135,450,21.2132,,0.048580374
25.92832262,45.135,410,20.2485,,0.044262118
26.00710432,45.135,364,19.0788,,0.039296124
26.08588602,45.135,403,20.0749,,0.043506423
26.16466771,45.135,387,19.6723,,0.041779121
26.24344941,45.135,406,20.1494,,0.043830293
26.32223111,45.135,407,20.1742,,0.043938249
26.4010128,45.135,388,19.6977,,0.041887078
26.4797945,45.135,350,18.7083,,0.037784735
26.55857619,45.135,371,19.2614,,0.040051819
26.63735789,45.135,422,20.5426,,0.045557595
26.71613959,45.135,435,20.8567,,0.046961028
26.79492128,45.135,369,19.2094,,0.039835906
26.87370298,45.135,409,20.2237,,0.044154162
26.95248467,45.135,368,19.1833,,0.03972795
27.03126637,45.135,419,20.4695,,0.045233726
27.11004807,45.135,399,19.975,,0.043074598
27.18882976,45.135,354,18.8149,,0.038216561
27.26761146,45.135,468,21.6333,,0.050523588
27.34639315,45.135,383,19.5704,,0.041347296
27.42517485,45.135,427,20.664,,0.046097377
27.50395655,45.135,364,19.0788,,0.039296124
27.58273824,45.135,452,21.2603,,0.048796286
27.66151994,45.135,398,19.9499,,0.042966641
27.74030163,45.135,390,19.7484,,0.04210299
27.81908333,45.135,447,21.1424,,0.048256504
27.89786503,45.135,444,21.0713,,0.047932635
27.97664672,45.135,425,20.6155,,0.045881464
28.05542842,45.135,403,20.0749,,0.043506423
28.13421011,45.135,438,20.9284,,0.047284897
28.21299181,45.135,404,20.0998,,0.04361438
28.29177351,45.135,422,20.5426,,0.045557595
28.3705552,45.135,441,21,,0.047608766
28.4493369,45.135,382,19.5448,,0.041239339
28.52811859,45.135,380,19.4936,,0.041023427
28.60690029,45.135,411,20.2731,,0.044370074
28.68568199,45.135,381,19.5192,,0.041131383
28.76446368,45.135,362,19.0263,,0.039080212
28.84324538,45.135,346,18.6011,,0.037352909
28.92202708,45.135,413,20.3224,,0.044585987
29.00080877,45.135,367,19.1572,,0.039619994
29.07959047,45.135,383,19.5704,,0.041347296
29.15837216,45.135,351,18.735,,0.037892691
29.23715386,45.135,368,19.1833,,0.03972795
29.31593556,45.135,362,19.0263,,0.039080212
29.39471725,45.135,383,19.5704,,0.041347296
29.47349895,45.135,383,19.5704,,0.041347296
29.55228064,45.135,393,19.8242,,0.04242686
29.63106234,45.135,356,18.868,,0.038432473
29.70984404,45.135,342,18.4932,,0.036921084
29.78862573,45.135,340,18.4391,,0.036705171
29.86740743,45.135,384,19.5959,,0.041455252
29.94618912,45.135,405,20.1246,,0.043722336
30.02497082,45.135,352,18.7617,,0.038000648
30.10375252,45.135,353,18.7883,,0.038108604
30.18253421,45.135,352,18.7617,,0.038000648
30.26131591,45.135,385,19.6214,,0.041563208
30.3400976,45.135,336,18.3303,,0.036273346
30.4188793,45.135,350,18.7083,,0.037784735
30.497661,45.135,398,19.9499,,0.042966641
30.57644269,45.135,363,19.0526,,0.039188168
30.65522439,45.135,373,19.3132,,0.040267732
30.73400608,45.135,367,19.1572,,0.039619994
30.81278778,45.135,344,18.5472,,0.037136997
30.89156948,45.135,385,19.6214,,0.041563208
30.97035117,45.135,359,18.9473,,0.038756342
31.04913287,45.135,376,19.3907,,0.040591601
31.12791456,45.135,372,19.2873,,0.040159775
31.20669626,45.135,389,19.7231,,0.041995034
31.28547796,45.135,375,19.3649,,0.040483645
31.36425965,45.135,390,19.7484,,0.04210299
31.44304135,45.135,382,19.5448,,0.041239339
31.52182304,45.135,386,19.6469,,0.041671165
31.60060474,45.135,338,18.3848,,0.036489258
31.67938644,45.135,377,19.4165,,0.040699557
31.75816813,45.135,381,19.5192,,0.041131383
31.83694983,45.135,369,19.2094,,0.039835906
31.91573153,45.135,387,19.6723,,0.041779121
31.99451322,45.135,474,21.7715,,0.051171327
32.07329492,45.135,646,25.4165,,0.069739825
32.15207661,45.135,1233,35.1141,,0.133110223
32.23085831,45.135,2838,53.2729,,0.306380222
32.30964001,45.135,2764,52.5738,,0.29839145
32.3884217,45.135,1457,38.1707,,0.157292454
32.4672034,45.135,624,24.98,,0.067364785
32.54598509,45.135,484,22,,0.052250891
32.62476679,45.135,457,21.3776,,0.049336068
32.70354849,45.135,432,20.7846,,0.046637159
32.78233018,45.135,439,20.9523,,0.047392853
32.86111188,45.135,410,20.2485,,0.044262118
32.93989357,45.135,459,21.4243,,0.049551981
33.01867527,45.135,372,19.2873,,0.040159775
33.09745697,45.135,402,20.0499,,0.043398467
33.17623866,45.135,403,20.0749,,0.043506423
33.25502036,45.135,388,19.6977,,0.041887078
33.33380205,45.135,386,19.6469,,0.041671165
33.41258375,45.135,371,19.2614,,0.040051819
33.49136545,45.135,390,19.7484,,0.04210299
33.57014714,45.135,349,18.6815,,0.037676779
33.64892884,45.135,371,19.2614,,0.040051819
33.72771053,45.135,398,19.9499,,0.042966641
33.80649223,45.135,359,18.9473,,0.038756342
33.88527393,45.135,400,20,,0.043182554
33.96405562,45.135,397,19.9249,,0.042858685
34.04283732,45.135,378,19.4422,,0.040807514
34.12161901,45.135,448,21.166,,0.048364461
34.20040071,45.135,516,22.7156,,0.055705495
34.27918241,45.135,699,26.4386,,0.075461514
34.3579641,45.135,1244,35.2704,,0.134297744
34.4367458,45.135,2632,51.303,,0.284141207
34.5155275,45.135,2732,52.2685,,0.294936846
34.59430919,45.135,1749,41.821,,0.188815718
34.67309089,45.135,878,29.6311,,0.094785707
34.75187258,45.135,554,23.5372,,0.059807838
34.83065428,45.135,444,21.0713,,0.047932635
34.90943598,45.135,427,20.664,,0.046097377
34.98821767,45.135,394,19.8494,,0.042534816
35.06699937,45.135,383,19.5704,,0.041347296
35.14578106,45.135,414,20.347,,0.044693944
35.22456276,45.135,381,19.5192,,0.041131383
35.30334446,45.135,424,20.5913,,0.045773508
35.38212615,45.135,427,20.664,,0.046097377
35.46090785,45.135,461,21.4709,,0.049767894
35.53968954,45.135,443,21.0476,,0.047824679
35.61847124,45.135,437,20.9045,,0.047176941
35.69725294,45.135,429,20.7123,,0.046313289
35.77603463,45.135,451,21.2368,,0.04868833
35.85481633,45.135,497,22.2935,,0.053654324
35.93359802,45.135,454,21.3073,,0.049012199
36.01237972,45.135,475,21.7945,,0.051279283
36.09116142,45.135,461,21.4709,,0.049767894
36.16994311,45.135,505,22.4722,,0.054517975
36.24872481,45.135,579,24.0624,,0.062506747
36.3275065,45.135,638,25.2587,,0.068876174
36.4062882,45.135,842,29.0172,,0.090899277
36.4850699,45.135,1332,36.4966,,0.143797906
36.56385159,45.135,2991,54.69,,0.322897549
36.64263329,45.135,7515,86.6891,,0.811292238
36.72141498,45.135,9263,96.2445,,1
36.80019668,45.135,5795,76.1249,,0.625607255
36.87897838,45.135,2407,49.0612,,0.25985102
36.95776007,45.135,1027,32.0468,,0.110871208
37.03654177,45.135,678,26.0384,,0.073194429
37.11532347,45.135,564,23.7487,,0.060887401
37.19410516,45.135,505,22.4722,,0.054517975
37.27288686,45.135,465,21.5639,,0.050199719
37.35166855,45.135,416,20.3961,,0.044909856
37.43045025,45.135,431,20.7605,,0.046529202
37.50923195,45.135,380,19.4936,,0.041023427
37.58801364,45.135,405,20.1246,,0.043722336
37.66679534,45.135,394,19.8494,,0.042534816
37.74557703,45.135,407,20.1742,,0.043938249
37.82435873,45.135,404,20.0998,,0.04361438
37.90314043,45.135,367,19.1572,,0.039619994
37.98192212,45.135,381,19.5192,,0.041131383
38.06070382,45.135,372,19.2873,,0.040159775
38.13948551,45.135,356,18.868,,0.038432473
38.21826721,45.135,342,18.4932,,0.036921084
38.29704891,45.135,323,17.9722,,0.034869913
38.3758306,45.135,390,19.7484,,0.04210299
38.4546123,45.135,375,19.3649,,0.040483645
38.53339399,45.135,373,19.3132,,0.040267732
38.61217569,45.135,355,18.8414,,0.038324517
38.69095739,45.135,372,19.2873,,0.040159775
38.76973908,45.135,324,18,,0.034977869
38.84852078,45.135,363,19.0526,,0.039188168
38.92730247,45.135,338,18.3848,,0.036489258
39.00608417,45.135,345,18.5742,,0.037244953
39.08486587,45.135,360,18.9737,,0.038864299
39.16364756,45.135,334,18.2757,,0.036057433
39.24242926,45.135,372,19.2873,,0.040159775
39.32121095,45.135,318,17.8326,,0.034330131
39.39999265,45.135,323,17.9722,,0.034869913
39.47877435,45.135,360,18.9737,,0.038864299
39.55755604,45.135,360,18.9737,,0.038864299
39.63633774,45.135,359,18.9473,,0.038756342
39.71511943,45.135,345,18.5742,,0.037244953
39.79390113,45.135,332,18.2209,,0.03584152
39.87268283,45.135,344,18.5472,,0.037136997
39.95146452,45.135,356,18.868,,0.038432473
40.03024622,45.135,367,19.1572,,0.039619994
40.10902792,45.135,342,18.4932,,0.036921084
40.18780961,45.135,354,18.8149,,0.038216561
40.26659131,45.135,340,18.4391,,0.036705171
40.345373,45.135,347,18.6279,,0.037460866
40.4241547,45.135,317,17.8045,,0.034222174
40.5029364,45.135,318,17.8326,,0.034330131
40.58171809,45.135,344,18.5472,,0.037136997
40.66049979,45.135,343,18.5203,,0.03702904
40.73928148,45.135,328,18.1108,,0.035409694
40.81806318,45.135,349,18.6815,,0.037676779
40.89684488,45.135,320,17.8885,,0.034546043
40.97562657,45.135,312,17.6635,,0.033682392
41.05440827,45.135,312,17.6635,,0.033682392
41.13318996,45.135,336,18.3303,,0.036273346
41.21197166,45.135,335,18.303,,0.036165389
41.29075336,45.135,361,19,,0.038972255
41.36953505,45.135,326,18.0555,,0.035193782
41.44831675,45.135,300,17.3205,,0.032386916
41.52709844,45.135,368,19.1833,,0.03972795
41.60588014,45.135,309,17.5784,,0.033358523
41.68466184,45.135,322,17.9444,,0.034761956
41.76344353,45.135,324,18,,0.034977869
41.84222523,45.135,337,18.3576,,0.036381302
41.92100692,45.135,339,18.412,,0.036597215
41.99978862,45.135,330,18.1659,,0.035625607
42.07857032,45.135,315,17.7482,,0.034006261
42.15735201,45.135,331,18.1934,,0.035733564
42.23613371,45.135,342,18.4932,,0.036921084
42.3149154,45.135,336,18.3303,,0.036273346
42.3936971,45.135,312,17.6635,,0.033682392
42.4724788,45.135,322,17.9444,,0.034761956
42.55126049,45.135,343,18.5203,,0.03702904
42.63004219,45.135,344,18.5472,,0.037136997
42.70882389,45.135,353,18.7883,,0.038108604
42.78760558,45.135,302,17.3781,,0.032602828
42.86638728,45.135,329,18.1384,,0.035517651
42.94516897,45.135,341,18.4662,,0.036813127
43.02395067,45.135,338,18.3848,,0.036489258
43.10273237,45.135,329,18.1384,,0.035517651
43.18151406,45.135,341,18.4662,,0.036813127
43.26029576,45.135,316,17.7764,,0.034114218
43.33907745,45.135,339,18.412,,0.036597215
43.41785915,45.135,311,17.6352,,0.033574436
43.49664085,45.135,320,17.8885,,0.034546043
43.57542254,45.135,308,17.5499,,0.033250567
43.65420424,45.135,293,17.1172,,0.031631221
43.73298593,45.135,303,17.4069,,0.032710785
43.81176763,45.135,284,16.8523,,0.030659614
43.89054933,45.135,254,15.9374,,0.027420922
43.96933102,45.135,316,17.7764,,0.034114218
44.04811272,45.135,319,17.8606,,0.034438087
44.12689441,45.135,289,17,,0.031199395
44.20567611,45.135,315,17.7482,,0.034006261
44.28445781,45.135,315,17.7482,,0.034006261
44.3632395,45.135,295,17.1756,,0.031847134
44.4420212,45.135,308,17.5499,,0.033250567
44.52080289,45.135,300,17.3205,,0.032386916
44.59958459,45.135,297,17.2337,,0.032063047
44.67836629,45.135,309,17.5784,,0.033358523
44.75714798,45.135,286,16.9115,,0.030875526
44.83592968,45.135,291,17.0587,,0.031415308
44.91471137,45.135,323,17.9722,,0.034869913
44.99349307,45.135,277,16.6433,,0.029903919
45.07227477,45.135,300,17.3205,,0.032386916
45.15105646,45.135,312,17.6635,,0.033682392
45.22983816,45.135,295,17.1756,,0.031847134
45.30861986,45.135,303,17.4069,,0.032710785
45.38740155,45.135,300,17.3205,,0.032386916
45.46618325,45.135,326,18.0555,,0.035193782
45.54496494,45.135,300,17.3205,,0.032386916
45.62374664,45.135,289,17,,0.031199395
45.70252834,45.135,312,17.6635,,0.033682392
45.78131003,45.135,269,16.4012,,0.029040268
45.86009173,45.135,286,16.9115,,0.030875526
45.93887342,45.135,286,16.9115,,0.030875526
46.01765512,45.135,331,18.1934,,0.035733564
46.09643682,45.135,319,17.8606,,0.034438087
46.17521851,45.135,330,18.1659,,0.035625607
46.25400021,45.135,298,17.2627,,0.032171003
46.3327819,45.135,310,17.6068,,0.03346648
46.4115636,45.135,315,17.7482,,0.034006261
46.4903453,45.135,334,18.2757,,0.036057433
46.56912699,45.135,317,17.8045,,0.034222174
46.64790869,45.135,362,19.0263,,0.039080212
46.72669038,45.135,299,17.2916,,0.032278959
46.80547208,45.135,301,17.3494,,0.032494872
46.88425378,45.135,316,17.7764,,0.034114218
46.96303547,45.135,296,17.2047,,0.03195509
47.04181717,45.135,306,17.4929,,0.033034654
47.12059886,45.135,351,18.735,,0.037892691
47.19938056,45.135,320,17.8885,,0.034546043
47.27816226,45.135,298,17.2627,,0.032171003
47.35694395,45.135,300,17.3205,,0.032386916
47.43572565,45.135,295,17.1756,,0.031847134
47.51450734,45.135,327,18.0831,,0.035301738
47.59328904,45.135,405,20.1246,,0.043722336
47.67207074,45.135,387,19.6723,,0.041779121
47.75085243,45.135,548,23.4094,,0.059160099
47.82963413,45.135,963,31.0322,,0.103961999
47.90841582,45.135,1209,34.7707,,0.13051927
47.98719752,45.135,1024,32,,0.110547339
48.06597922,45.135,652,25.5343,,0.070387563
48.14476091,45.135,428,20.6882,,0.046205333
48.22354261,45.135,368,19.1833,,0.03972795
48.30232431,45.135,319,17.8606,,0.034438087
48.381106,45.135,325,18.0278,,0.035085825
48.4598877,45.135,317,17.8045,,0.034222174
48.53866939,45.135,321,17.9165,,0.034654
48.61745109,45.135,290,17.0294,,0.031307352
48.69623279,45.135,302,17.3781,,0.032602828
48.77501448,45.135,309,17.5784,,0.033358523
48.85379618,45.135,250,15.8114,,0.026989096
48.93257787,45.135,290,17.0294,,0.031307352
49.01135957,45.135,293,17.1172,,0.031631221
49.09014127,45.135,290,17.0294,,0.031307352
49.16892296,45.135,288,16.9706,,0.031091439
49.24770466,45.135,292,17.088,,0.031523265
49.32648635,45.135,269,16.4012,,0.029040268
49.40526805,45.135,266,16.3095,,0.028716399
49.48404975,45.135,307,17.5214,,0.03314261
49.56283144,45.135,275,16.5831,,0.029688006
49.64161314,45.135,272,16.4924,,0.029364137
49.72039483,45.135,258,16.0624,,0.027852747
49.79917653,45.135,276,16.6132,,0.029795962
49.87795823,45.135,294,17.1464,,0.031739177
49.95673992,45.135,320,17.8885,,0.034546043
50.03552162,45.135,303,17.4069,,0.032710785
50.11430331,45.135,280,16.7332,,0.030227788
50.19308501,45.135,284,16.8523,,0.030659614
50.27186671,45.135,283,16.8226,,0.030551657
50.3506484,45.135,252,15.8745,,0.027205009
50.4294301,45.135,237,15.3948,,0.025585663
50.50821179,45.135,294,17.1464,,0.031739177
50.58699349,45.135,307,17.5214,,0.03314261
50.66577519,45.135,261,16.1555,,0.028176617
50.74455688,45.135,262,16.1864,,0.028284573
50.82333858,45.135,289,17,,0.031199395
50.90212028,45.135,267,16.3401,,0.028824355
50.98090197,45.135,319,17.8606,,0.034438087
51.05968367,45.135,270,16.4317,,0.029148224
51.13846536,45.135,303,17.4069,,0.032710785
51.21724706,45.135,268,16.3707,,0.028932311
51.29602876,45.135,263,16.2173,,0.028392529
51.37481045,45.135,269,16.4012,,0.029040268
51.45359215,45.135,279,16.7033,,0.030119832
51.53237384,45.135,263,16.2173,,0.028392529
51.61115554,45.135,293,17.1172,,0.031631221
51.68993724,45.135,260,16.1245,,0.02806866
51.76871893,45.135,263,16.2173,,0.028392529
51.84750063,45.135,267,16.3401,,0.028824355
51.92628232,45.135,258,16.0624,,0.027852747
52.00506402,45.135,291,17.0587,,0.031415308
52.08384572,45.135,290,17.0294,,0.031307352
52.16262741,45.135,250,15.8114,,0.026989096
52.24140911,45.135,281,16.7631,,0.030335744
52.3201908,45.135,255,15.9687,,0.027528878
52.3989725,45.135,277,16.6433,,0.029903919
52.4777542,45.135,285,16.8819,,0.03076757
52.55653589,45.135,262,16.1864,,0.028284573
52.63531759,45.135,300,17.3205,,0.032386916
52.71409928,45.135,259,16.0935,,0.027960704
52.79288098,45.135,253,15.906,,0.027312966
52.87166268,45.135,283,16.8226,,0.030551657
52.95044437,45.135,263,16.2173,,0.028392529
53.02922607,45.135,288,16.9706,,0.031091439
53.10800776,45.135,245,15.6525,,0.026449314
53.18678946,45.135,265,16.2788,,0.028608442
53.26557116,45.135,275,16.5831,,0.029688006
53.34435285,45.135,249,15.7797,,0.02688114
53.42313455,45.135,241,15.5242,,0.026017489
53.50191625,45.135,256,16,,0.027636835
53.58069794,45.135,289,17,,0.031199395
53.65947964,45.135,216,14.6969,,0.023318579
53.73826133,45.135,281,16.7631,,0.030335744
53.81704303,45.135,243,15.5885,,0.026233402
53.89582473,45.135,231,15.1987,,0.024937925
53.97460642,45.135,243,15.5885,,0.026233402
54.05338812,45.135,265,16.2788,,0.028608442
54.13216981,45.135,280,16.7332,,0.030227788
54.21095151,45.135,264,16.2481,,0.028500486
54.28973321,45.135,264,16.2481,,0.028500486
54.3685149,45.135,236,15.3623,,0.025477707
54.4472966,45.135,254,15.9374,,0.027420922
54.52607829,45.135,257,16.0312,,0.027744791
54.60485999,45.135,255,15.9687,,0.027528878
54.68364169,45.135,263,16.2173,,0.028392529
54.76242338,45.135,248,15.748,,0.026773184
54.84120508,45.135,292,17.088,,0.031523265
54.91998677,45.135,263,16.2173,,0.028392529
54.99876847,45.135,281,16.7631,,0.030335744
55.07755017,45.135,239,15.4596,,0.025801576
55.15633186,45.135,245,15.6525,,0.026449314
55.23511356,45.135,264,16.2481,,0.028500486
55.31389525,45.135,243,15.5885,,0.026233402
55.39267695,45.135,248,15.748,,0.026773184
55.47145865,45.135,212,14.5602,,0.022886754
55.55024034,45.135,244,15.6205,,0.026341358
55.62902204,45.135,215,14.6629,,0.023210623
55.70780373,45.135,270,16.4317,,0.029148224
55.78658543,45.135,256,16,,0.027636835
55.86536713,45.135,263,16.2173,,0.028392529
55.94414882,45.135,247,15.7162,,0.026665227
56.02293052,45.135,253,15.906,,0.027312966
56.10171221,45.135,266,16.3095,,0.028716399
56.18049391,45.135,243,15.5885,,0.026233402
56.25927561,45.135,251,15.843,,0.027097053
56.3380573,45.135,266,16.3095,,0.028716399
56.416839,45.135,268,16.3707,,0.028932311
56.4956207,45.135,258,16.0624,,0.027852747
56.57440239,45.135,258,16.0624,,0.027852747
56.65318409,45.135,235,15.3297,,0.025369751
56.73196578,45.135,249,15.7797,,0.02688114
56.81074748,45.135,255,15.9687,,0.027528878
56.88952918,45.135,223,14.9332,,0.024074274
56.96831087,45.135,256,16,,0.027636835
57.04709257,45.135,294,17.1464,,0.031739177
57.12587426,45.135,296,17.2047,,0.03195509
57.20465596,45.135,325,18.0278,,0.035085825
57.28343766,45.135,404,20.0998,,0.04361438
57.36221935,45.135,715,26.7395,,0.077188816
57.44100105,45.135,1150,33.9116,,0.124149843
57.51978274,45.135,864,29.3939,,0.093274317
57.59856444,45.135,738,27.1662,,0.079671813
57.67734614,45.135,524,22.891,,0.056569146
57.75612783,45.135,389,19.7231,,0.041995034
57.83490953,45.135,271,16.4621,,0.029256181
57.91369122,45.135,283,16.8226,,0.030551657
57.99247292,45.135,220,14.8324,,0.023750405
58.07125462,45.135,248,15.748,,0.026773184
58.15003631,45.135,210,14.4914,,0.022670841
58.22881801,45.135,243,15.5885,,0.026233402
58.3075997,45.135,268,16.3707,,0.028932311
58.3863814,45.135,257,16.0312,,0.027744791
58.4651631,45.135,227,15.0665,,0.0245061
58.54394479,45.135,234,15.2971,,0.025261794
58.62272649,45.135,219,14.7986,,0.023642448
58.70150818,45.135,228,15.0997,,0.024614056
58.78028988,45.135,220,14.8324,,0.023750405
58.85907158,45.135,234,15.2971,,0.025261794
58.93785327,45.135,229,15.1327,,0.024722012
59.01663497,45.135,231,15.1987,,0.024937925
59.09541667,45.135,234,15.2971,,0.025261794
59.17419836,45.135,228,15.0997,,0.024614056
59.25298006,45.135,217,14.7309,,0.023426536
59.33176175,45.135,253,15.906,,0.027312966
59.41054345,45.135,239,15.4596,,0.025801576
59.48932515,45.135,230,15.1658,,0.024829969
59.56810684,45.135,190,13.784,,0.020511713
59.64688854,45.135,253,15.906,,0.027312966
59.72567023,45.135,216,14.6969,,0.023318579
59.80445193,45.135,223,14.9332,,0.024074274
59.88323363,45.135,226,15.0333,,0.024398143
59.96201532,45.135,251,15.843,,0.027097053
60.04079702,45.135,227,15.0665,,0.0245061
60.11957871,45.135,236,15.3623,,0.025477707
60.19836041,45.135,188,13.7113,,0.0202958
60.27714211,45.135,256,16,,0.027636835
60.3559238,45.135,256,16,,0.027636835
60.4347055,45.135,192,13.8564,,0.020727626
60.51348719,45.135,219,14.7986,,0.023642448
60.59226889,45.135,207,14.3875,,0.022346972
60.67105059,45.135,243,15.5885,,0.026233402
60.74983228,45.135,254,15.9374,,0.027420922
60.82861398,45.135,245,15.6525,,0.026449314
60.90739567,45.135,230,15.1658,,0.024829969
60.98617737,45.135,232,15.2315,,0.025045881
61.06495907,45.135,208,14.4222,,0.022454928
61.14374076,45.135,264,16.2481,,0.028500486
61.22252246,45.135,245,15.6525,,0.026449314
61.30130415,45.135,234,15.2971,,0.025261794
61.38008585,45.135,245,15.6525,,0.026449314
61.45886755,45.135,234,15.2971,,0.025261794
61.53764924,45.135,245,15.6525,,0.026449314
61.61643094,45.135,204,14.2829,,0.022023103
61.69521264,45.135,252,15.8745,,0.027205009
61.77399433,45.135,247,15.7162,,0.026665227
61.85277603,45.135,219,14.7986,,0.023642448
61.93155772,45.135,215,14.6629,,0.023210623
62.01033942,45.135,258,16.0624,,0.027852747
62.08912112,45.135,228,15.0997,,0.024614056
62.16790281,45.135,246,15.6844,,0.026557271
62.24668451,45.135,243,15.5885,,0.026233402
62.3254662,45.135,257,16.0312,,0.027744791
62.4042479,45.135,230,15.1658,,0.024829969
62.4830296,45.135,230,15.1658,,0.024829969
62.56181129,45.135,254,15.9374,,0.027420922
62.64059299,45.135,240,15.4919,,0.025909533
62.71937468,45.135,286,16.9115,,0.030875526
62.79815638,45.135,251,15.843,,0.027097053
62.87693808,45.135,311,17.6352,,0.033574436
62.95571977,45.135,368,19.1833,,0.03972795
63.03450147,45.135,561,23.6854,,0.060563532
63.11328316,45.135,959,30.9677,,0.103530174
63.19206486,45.135,882,29.6985,,0.095217532
63.27084656,45.135,722,26.8701,,0.07794451
63.34962825,45.135,620,24.8998,,0.066932959
63.42840995,45.135,422,20.5426,,0.045557595
63.50719164,45.135,286,16.9115,,0.030875526
63.58597334,45.135,253,15.906,,0.027312966
63.66475504,45.135,276,16.6132,,0.029795962
63.74353673,45.135,227,15.0665,,0.0245061
63.82231843,45.135,218,14.7648,,0.023534492
63.90110012,45.135,191,13.8203,,0.02061967
63.97988182,45.135,217,14.7309,,0.023426536
64.05866352,45.135,204,14.2829,,0.022023103
64.13744521,45.135,202,14.2127,,0.02180719
64.21622691,45.135,217,14.7309,,0.023426536
64.2950086,45.135,210,14.4914,,0.022670841
64.3737903,45.135,210,14.4914,,0.022670841
64.452572,45.135,195,13.9642,,0.021051495
64.53135369,45.135,212,14.5602,,0.022886754
64.61013539,45.135,216,14.6969,,0.023318579
64.68891709,45.135,193,13.8924,,0.020835582
64.76769878,45.135,179,13.3791,,0.019324193
64.84648048,45.135,183,13.5277,,0.019756019
64.92526217,45.135,201,14.1774,,0.021699234
65.00404387,45.135,197,14.0357,,0.021267408
65.08282557,45.135,184,13.5647,,0.019863975
65.16160726,45.135,209,14.4568,,0.022562885
65.24038896,45.135,218,14.7648,,0.023534492
65.31917065,45.135,228,15.0997,,0.024614056
65.39795235,45.135,227,15.0665,,0.0245061
65.47673405,45.135,199,14.1067,,0.021483321
65.55551574,45.135,201,14.1774,,0.021699234
65.63429744,45.135,212,14.5602,,0.022886754
65.71307913,45.135,209,14.4568,,0.022562885
65.79186083,45.135,199,14.1067,,0.021483321
65.87064253,45.135,203,14.2478,,0.021915146
65.94942422,45.135,198,14.0712,,0.021375364
66.02820592,45.135,233,15.2643,,0.025153838
66.10698761,45.135,208,14.4222,,0.022454928
66.18576931,45.135,174,13.1909,,0.018784411
66.26455101,45.135,219,14.7986,,0.023642448
66.3433327,45.135,197,14.0357,,0.021267408
66.4221144,45.135,185,13.6015,,0.019971931
66.50089609,45.135,181,13.4536,,0.019540106
66.57967779,45.135,203,14.2478,,0.021915146
66.65845949,45.135,211,14.5258,,0.022778797
66.73724118,45.135,180,13.4164,,0.019432149
66.81602288,45.135,207,14.3875,,0.022346972
66.89480457,45.135,190,13.784,,0.020511713
66.97358627,45.135,214,14.6287,,0.023102667
67.05236797,45.135,184,13.5647,,0.019863975
67.13114966,45.135,220,14.8324,,0.023750405
67.20993136,45.135,217,14.7309,,0.023426536
67.28871306,45.135,217,14.7309,,0.023426536
67.36749475,45.135,295,17.1756,,0.031847134
67.44627645,45.135,262,16.1864,,0.028284573
67.52505814,45.135,249,15.7797,,0.02688114
67.60383984,45.135,265,16.2788,,0.028608442
67.68262154,45.135,212,14.5602,,0.022886754
67.76140323,45.135,236,15.3623,,0.025477707
67.84018493,45.135,221,14.8661,,0.023858361
67.91896662,45.135,228,15.0997,,0.024614056
67.99774832,45.135,215,14.6629,,0.023210623
68.07653002,45.135,204,14.2829,,0.022023103
68.15531171,45.135,226,15.0333,,0.024398143
68.23409341,45.135,217,14.7309,,0.023426536
68.3128751,45.135,227,15.0665,,0.0245061
68.3916568,45.135,273,16.5227,,0.029472093
68.4704385,45.135,291,17.0587,,0.031415308
68.54922019,45.135,348,18.6548,,0.037568822
68.62800189,45.135,594,24.3721,,0.064126093
68.70678358,45.135,965,31.0644,,0.104177912
68.78556528,45.135,641,25.318,,0.069200043
68.86434698,45.135,601,24.5153,,0.064881788
68.94312867,45.135,559,23.6432,,0.06034762
69.02191037,45.135,292,17.088,,0.031523265
69.10069206,45.135,256,16,,0.027636835
69.17947376,45.135,267,16.3401,,0.028824355
69.25825546,45.135,204,14.2829,,0.022023103
69.33703715,45.135,226,15.0333,,0.024398143
69.41581885,45.135,207,14.3875,,0.022346972
69.49460054,45.135,204,14.2829,,0.022023103
69.57338224,45.135,223,14.9332,,0.024074274
69.65216394,45.135,199,14.1067,,0.021483321
69.73094563,45.135,268,16.3707,,0.028932311
69.80972733,45.135,249,15.7797,,0.02688114
69.88850903,45.135,252,15.8745,,0.027205009
69.96729072,45.135,344,18.5472,,0.037136997
70.04607242,45.135,641,25.318,,0.069200043
70.12485411,45.135,637,25.2389,,0.068768218
70.20363581,45.135,496,22.2711,,0.053546367
70.28241751,45.135,515,22.6936,,0.055597539
70.3611992,45.135,349,18.6815,,0.037676779
70.4399809,45.135,220,14.8324,,0.023750405
70.51876259,45.135,199,14.1067,,0.021483321
70.59754429,45.135,182,13.4907,,0.019648062
70.67632599,45.135,219,14.7986,,0.023642448
70.75510768,45.135,205,14.3178,,0.022131059
70.83388938,45.135,193,13.8924,,0.020835582
70.91267107,45.135,197,14.0357,,0.021267408
70.99145277,45.135,228,15.0997,,0.024614056
71.07023447,45.135,181,13.4536,,0.019540106
71.14901616,45.135,207,14.3875,,0.022346972
71.22779786,45.135,182,13.4907,,0.019648062
71.30657955,45.135,167,12.9228,,0.018028716
71.38536125,45.135,183,13.5277,,0.019756019
71.46414295,45.135,167,12.9228,,0.018028716
71.54292464,45.135,171,13.0767,,0.018460542
71.62170634,45.135,178,13.3417,,0.019216237
71.70048803,45.135,183,13.5277,,0.019756019
71.77926973,45.135,180,13.4164,,0.019432149
71.85805143,45.135,197,14.0357,,0.021267408
71.93683312,45.135,189,13.7477,,0.020403757
72.01561482,45.135,182,13.4907,,0.019648062
72.09439651,45.135,203,14.2478,,0.021915146
72.17317821,45.135,149,12.2066,,0.016085501
72.25195991,45.135,185,13.6015,,0.019971931
72.3307416,45.135,186,13.6382,,0.020079888
72.4095233,45.135,191,13.8203,,0.02061967
72.488305,45.135,216,14.6969,,0.023318579
72.56708669,45.135,278,16.6733,,0.030011875
72.64586839,45.135,247,15.7162,,0.026665227
72.72465008,45.135,237,15.3948,,0.025585663
72.80343178,45.135,221,14.8661,,0.023858361
72.88221348,45.135,202,14.2127,,0.02180719
72.96099517,45.135,204,14.2829,,0.022023103
73.03977687,45.135,176,13.2665,,0.019000324
73.11855856,45.135,191,13.8203,,0.02061967
73.19734026,45.135,178,13.3417,,0.019216237
73.27612196,45.135,193,13.8924,,0.020835582
73.35490365,45.135,180,13.4164,,0.019432149
73.43368535,45.135,174,13.1909,,0.018784411
73.51246704,45.135,190,13.784,,0.020511713
73.59124874,45.135,190,13.784,,0.020511713
73.67003044,45.135,179,13.3791,,0.019324193
73.74881213,45.135,183,13.5277,,0.019756019
73.82759383,45.135,177,13.3041,,0.01910828
73.90637552,45.135,159,12.6095,,0.017165065
73.98515722,45.135,158,12.5698,,0.017057109
74.06393892,45.135,156,12.49,,0.016841196
74.14272061,45.135,203,14.2478,,0.021915146
74.22150231,45.135,185,13.6015,,0.019971931
74.300284,45.135,182,13.4907,,0.019648062
74.3790657,45.135,166,12.8841,,0.01792076
74.4578474,45.135,151,12.2882,,0.016301414
74.53662909,45.135,181,13.4536,,0.019540106
74.61541079,45.135,170,13.0384,,0.018352586
74.69419248,45.135,156,12.49,,0.016841196
74.77297418,45.135,159,12.6095,,0.017165065
74.85175588,45.135,185,13.6015,,0.019971931
74.93053757,45.135,205,14.3178,,0.022131059
75.00931927,45.135,148,12.1655,,0.015977545
75.08810096,45.135,158,12.5698,,0.017057109
75.16688266,45.135,185,13.6015,,0.019971931
75.24566436,45.135,155,12.4499,,0.01673324
75.32444605,45.135,152,12.3288,,0.016409371
75.40322775,45.135,172,13.1149,,0.018568498
75.48200945,45.135,159,12.6095,,0.017165065
75.56079114,45.135,179,13.3791,,0.019324193
75.63957284,45.135,157,12.53,,0.016949153
75.71835453,45.135,177,13.3041,,0.01910828
75.79713623,45.135,165,12.8452,,0.017812804
75.87591793,45.135,177,13.3041,,0.01910828
75.95469962,45.135,159,12.6095,,0.017165065
76.03348132,45.135,166,12.8841,,0.01792076
76.11226301,45.135,173,13.1529,,0.018676455
76.19104471,45.135,209,14.4568,,0.022562885
76.26982641,45.135,185,13.6015,,0.019971931
76.3486081,45.135,164,12.8062,,0.017704847
76.4273898,45.135,152,12.3288,,0.016409371
76.50617149,45.135,181,13.4536,,0.019540106
76.58495319,45.135,174,13.1909,,0.018784411
76.66373489,45.135,149,12.2066,,0.016085501
76.74251658,45.135,182,13.4907,,0.019648062
76.82129828,45.135,185,13.6015,,0.019971931
76.90007997,45.135,175,13.2288,,0.018892367
76.97886167,45.135,174,13.1909,,0.018784411
77.05764337,45.135,177,13.3041,,0.01910828
77.13642506,45.135,201,14.1774,,0.021699234
77.21520676,45.135,205,14.3178,,0.022131059
77.29398845,45.135,188,13.7113,,0.0202958
77.37277015,45.135,198,14.0712,,0.021375364
77.45155185,45.135,162,12.7279,,0.017488934
77.53033354,45.135,191,13.8203,,0.02061967
77.60911524,45.135,168,12.9615,,0.018136673
77.68789693,45.135,189,13.7477,,0.020403757
77.76667863,45.135,207,14.3875,,0.022346972
77.84546033,45.135,225,15,,0.024290187
77.92424202,45.135,266,16.3095,,0.028716399
78.00302372,45.135,222,14.8997,,0.023966318
78.08180542,45.135,211,14.5258,,0.022778797
78.16058711,45.135,196,14,,0.021159452
78.23936881,45.135,209,14.4568,,0.022562885
78.3181505,45.135,167,12.9228,,0.018028716
78.3969322,45.135,193,13.8924,,0.020835582
78.4757139,45.135,186,13.6382,,0.020079888
78.55449559,45.135,177,13.3041,,0.01910828
78.63327729,45.135,177,13.3041,,0.01910828
78.71205898,45.135,165,12.8452,,0.017812804
78.79084068,45.135,179,13.3791,,0.019324193
78.86962238,45.135,168,12.9615,,0.018136673
78.94840407,45.135,164,12.8062,,0.017704847
79.02718577,45.135,179,13.3791,,0.019324193
79.10596746,45.135,161,12.6886,,0.017380978
79.18474916,45.135,134,11.5758,,0.014466156
79.26353086,45.135,133,11.5326,,0.014358199
79.34231255,45.135,152,12.3288,,0.016409371
79.42109425,45.135,132,11.4891,,0.014250243
79.49987594,45.135,164,12.8062,,0.017704847
79.57865764,45.135,164,12.8062,,0.017704847
79.65743934,45.135,134,11.5758,,0.014466156
79.73622103,45.135,133,11.5326,,0.014358199
79.81500273,45.135,155,12.4499,,0.01673324
79.89378442,45.135,159,12.6095,,0.017165065
79.97256612,45.135,175,13.2288,,0.018892367