File: sheets/60W.csv
[Measurement conditions],,,,,
Sample identification,,,,,
Comment - 1,"Configuration=Reflection-transmission spinner, Owner=User-1, Creation date=12/4/2012 10:13:13 AM",,,,
Comment - 2,Goniometer=Theta/Theta; Minimum step size 2Theta:0.0001; Minimum step size Omega:0.0001,,,,
Comment - 3,Sample stage=Reflection-transmission spinner; Minimum step size Phi:0.1,,,,
Comment - 4,Diffractometer system=EMPYREAN,,,,
Comment - 5,"Measurement program=C:\PANalytical\Data Collector\Programs\PI Lorenzo Mangolini\BrandonWagner_Mg.xrdmp, Identifier={9EE36770-7A59-4EAA-85D0-90E43AFBFC91}",,,,
Anode material,Cu,,,,
K-Alpha1 wavelength,1.540598,,,,
K-Alpha2 wavelength,1.544426,,,,
Ratio K-Alpha2/K-Alpha1,0.5,,,,
Divergence slit,Fixed,0.76mm,,,
Monochromator used,NO,,,,
Generator voltage,45,,,,
Tube current,40,,,,
File date and time,4/5/2023 15:47,,,,
Unit cell,,,,,
h k l, 0 0 0,,,,
Scan axis,Gonio,,,,
Scan range,20,79.99226154,,,
Scan step size,0.0393908,,,,
No. of points,1523,,,,
Scan type,CONTINUOUS,,,,
Phi,208.5,,,,
Time per step,45.135,,,,
[Scan points],,,,,
Angle, TimePerStep, Intensity, ESD,,
20.01969542,45.135,528,22.9783,7384,0.071505959
20.09847712,45.135,522,22.8473,,0.070693391
20.17725881,45.135,482,21.9545,,0.065276273
20.25604051,45.135,493,22.2036,,0.06676598
20.3348222,45.135,493,22.2036,,0.06676598
20.4136039,45.135,478,21.8632,,0.064734561
20.4923856,45.135,514,22.6716,,0.069609967
20.57116729,45.135,498,22.3159,,0.06744312
20.64994899,45.135,497,22.2935,,0.067307692
20.72873069,45.135,519,22.7816,,0.070287107
20.80751238,45.135,520,22.8035,,0.070422535
20.88629408,45.135,480,21.9089,,0.065005417
20.96507577,45.135,500,22.3607,,0.067713976
21.04385747,45.135,509,22.561,,0.068932828
21.12263917,45.135,472,21.7256,,0.063921993
21.20142086,45.135,473,21.7486,,0.064057421
21.28020256,45.135,472,21.7256,,0.063921993
21.35898425,45.135,481,21.9317,,0.065140845
21.43776595,45.135,456,21.3542,,0.061755146
21.51654765,45.135,470,21.6795,,0.063651138
21.59532934,45.135,463,21.5174,,0.062703142
21.67411104,45.135,478,21.8632,,0.064734561
21.75289273,45.135,467,21.6102,,0.063244854
21.83167443,45.135,470,21.6795,,0.063651138
21.91045613,45.135,469,21.6564,,0.06351571
21.98923782,45.135,437,20.9045,,0.059182015
22.06801952,45.135,493,22.2036,,0.06676598
22.14680121,45.135,455,21.3307,,0.061619718
22.22558291,45.135,461,21.4709,,0.062432286
22.30436461,45.135,477,21.8403,,0.064599133
22.3831463,45.135,449,21.1896,,0.060807151
22.461928,45.135,462,21.4942,,0.062567714
22.54070969,45.135,439,20.9523,,0.059452871
22.61949139,45.135,485,22.0227,,0.065682557
22.69827309,45.135,417,20.4206,,0.056473456
22.77705478,45.135,392,19.799,,0.053087757
22.85583648,45.135,447,21.1424,,0.060536295
22.93461817,45.135,415,20.3715,,0.0562026
23.01339987,45.135,424,20.5913,,0.057421452
23.09218157,45.135,464,21.5407,,0.06283857
23.17096326,45.135,432,20.7846,,0.058504875
23.24974496,45.135,408,20.199,,0.055254605
23.32852665,45.135,429,20.7123,,0.058098592
23.40730835,45.135,460,21.4476,,0.062296858
23.48609005,45.135,441,21,,0.059723727
23.56487174,45.135,453,21.2838,,0.061348862
23.64365344,45.135,391,19.7737,,0.052952329
23.72243514,45.135,459,21.4243,,0.06216143
23.80121683,45.135,446,21.1187,,0.060400867
23.87999853,45.135,419,20.4695,,0.056744312
23.95878022,45.135,424,20.5913,,0.057421452
24.03756192,45.135,426,20.6398,,0.057692308
24.11634362,45.135,444,21.0713,,0.060130011
24.19512531,45.135,405,20.1246,,0.054848321
24.27390701,45.135,408,20.199,,0.055254605
24.3526887,45.135,419,20.4695,,0.056744312
24.4314704,45.135,446,21.1187,,0.060400867
24.5102521,45.135,428,20.6882,,0.057963164
24.58903379,45.135,386,19.6469,,0.05227519
24.66781549,45.135,430,20.7364,,0.05823402
24.74659718,45.135,456,21.3542,,0.061755146
24.82537888,45.135,380,19.4936,,0.051462622
24.90416058,45.135,424,20.5913,,0.057421452
24.98294227,45.135,424,20.5913,,0.057421452
25.06172397,45.135,410,20.2485,,0.05552546
25.14050566,45.135,425,20.6155,,0.05755688
25.21928736,45.135,403,20.0749,,0.054577465
25.29806906,45.135,443,21.0476,,0.059994583
25.37685075,45.135,440,20.9762,,0.059588299
25.45563245,45.135,443,21.0476,,0.059994583
25.53441414,45.135,391,19.7737,,0.052952329
25.61319584,45.135,365,19.105,,0.049431203
25.69197754,45.135,398,19.9499,,0.053900325
25.77075923,45.135,362,19.0263,,0.049024919
25.84954093,45.135,378,19.4422,,0.051191766
25.92832262,45.135,433,20.8087,,0.058640303
26.00710432,45.135,387,19.6723,,0.052410618
26.08588602,45.135,412,20.2978,,0.055796316
26.16466771,45.135,369,19.2094,,0.049972914
26.24344941,45.135,406,20.1494,,0.054983749
26.32223111,45.135,420,20.4939,,0.05687974
26.4010128,45.135,389,19.7231,,0.052681473
26.4797945,45.135,385,19.6214,,0.052139762
26.55857619,45.135,395,19.8746,,0.053494041
26.63735789,45.135,389,19.7231,,0.052681473
26.71613959,45.135,397,19.9249,,0.053764897
26.79492128,45.135,375,19.3649,,0.050785482
26.87370298,45.135,423,20.567,,0.057286024
26.95248467,45.135,408,20.199,,0.055254605
27.03126637,45.135,436,20.8806,,0.059046587
27.11004807,45.135,410,20.2485,,0.05552546
27.18882976,45.135,419,20.4695,,0.056744312
27.26761146,45.135,396,19.8997,,0.053629469
27.34639315,45.135,414,20.347,,0.056067172
27.42517485,45.135,381,19.5192,,0.05159805
27.50395655,45.135,409,20.2237,,0.055390033
27.58273824,45.135,418,20.445,,0.056608884
27.66151994,45.135,423,20.567,,0.057286024
27.74030163,45.135,450,21.2132,,0.060942579
27.81908333,45.135,484,22,,0.065547129
27.89786503,45.135,525,22.9129,,0.071099675
27.97664672,45.135,610,24.6982,,0.082611051
28.05542842,45.135,572,23.9165,,0.077464789
28.13421011,45.135,545,23.3452,,0.073808234
28.21299181,45.135,460,21.4476,,0.062296858
28.29177351,45.135,475,21.7945,,0.064328277
28.3705552,45.135,414,20.347,,0.056067172
28.4493369,45.135,393,19.8242,,0.053223185
28.52811859,45.135,422,20.5426,,0.057150596
28.60690029,45.135,393,19.8242,,0.053223185
28.68568199,45.135,409,20.2237,,0.055390033
28.76446368,45.135,418,20.445,,0.056608884
28.84324538,45.135,394,19.8494,,0.053358613
28.92202708,45.135,386,19.6469,,0.05227519
29.00080877,45.135,397,19.9249,,0.053764897
29.07959047,45.135,361,19,,0.048889491
29.15837216,45.135,377,19.4165,,0.051056338
29.23715386,45.135,414,20.347,,0.056067172
29.31593556,45.135,383,19.5704,,0.051868906
29.39471725,45.135,382,19.5448,,0.051733478
29.47349895,45.135,342,18.4932,,0.04631636
29.55228064,45.135,376,19.3907,,0.05092091
29.63106234,45.135,390,19.7484,,0.052816901
29.70984404,45.135,326,18.0555,,0.044149512
29.78862573,45.135,385,19.6214,,0.052139762
29.86740743,45.135,379,19.4679,,0.051327194
29.94618912,45.135,364,19.0788,,0.049295775
30.02497082,45.135,357,18.8944,,0.048347779
30.10375252,45.135,357,18.8944,,0.048347779
30.18253421,45.135,370,19.2354,,0.050108342
30.26131591,45.135,342,18.4932,,0.04631636
30.3400976,45.135,345,18.5742,,0.046722644
30.4188793,45.135,366,19.1311,,0.049566631
30.497661,45.135,372,19.2873,,0.050379198
30.57644269,45.135,364,19.0788,,0.049295775
30.65522439,45.135,402,20.0499,,0.054442037
30.73400608,45.135,345,18.5742,,0.046722644
30.81278778,45.135,386,19.6469,,0.05227519
30.89156948,45.135,355,18.8414,,0.048076923
30.97035117,45.135,338,18.3848,,0.045774648
31.04913287,45.135,360,18.9737,,0.048754063
31.12791456,45.135,406,20.1494,,0.054983749
31.20669626,45.135,393,19.8242,,0.053223185
31.28547796,45.135,350,18.7083,,0.047399783
31.36425965,45.135,365,19.105,,0.049431203
31.44304135,45.135,338,18.3848,,0.045774648
31.52182304,45.135,420,20.4939,,0.05687974
31.60060474,45.135,384,19.5959,,0.052004334
31.67938644,45.135,383,19.5704,,0.051868906
31.75816813,45.135,378,19.4422,,0.051191766
31.83694983,45.135,390,19.7484,,0.052816901
31.91573153,45.135,390,19.7484,,0.052816901
31.99451322,45.135,438,20.9284,,0.059317443
32.07329492,45.135,580,24.0832,,0.078548212
32.15207661,45.135,1107,33.2716,,0.149918743
32.23085831,45.135,2227,47.1911,,0.30159805
32.30964001,45.135,2110,45.9347,,0.285752979
32.3884217,45.135,1165,34.1321,,0.157773564
32.4672034,45.135,570,23.8747,,0.077193933
32.54598509,45.135,436,20.8806,,0.059046587
32.62476679,45.135,441,21,,0.059723727
32.70354849,45.135,422,20.5426,,0.057150596
32.78233018,45.135,373,19.3132,,0.050514626
32.86111188,45.135,378,19.4422,,0.051191766
32.93989357,45.135,397,19.9249,,0.053764897
33.01867527,45.135,400,20,,0.054171181
33.09745697,45.135,387,19.6723,,0.052410618
33.17623866,45.135,394,19.8494,,0.053358613
33.25502036,45.135,389,19.7231,,0.052681473
33.33380205,45.135,359,18.9473,,0.048618635
33.41258375,45.135,363,19.0526,,0.049160347
33.49136545,45.135,372,19.2873,,0.050379198
33.57014714,45.135,388,19.6977,,0.052546046
33.64892884,45.135,349,18.6815,,0.047264355
33.72771053,45.135,362,19.0263,,0.049024919
33.80649223,45.135,393,19.8242,,0.053223185
33.88527393,45.135,398,19.9499,,0.053900325
33.96405562,45.135,381,19.5192,,0.05159805
34.04283732,45.135,437,20.9045,,0.059182015
34.12161901,45.135,385,19.6214,,0.052139762
34.20040071,45.135,509,22.561,,0.068932828
34.27918241,45.135,592,24.3311,,0.080173348
34.3579641,45.135,1057,32.5115,,0.143147346
34.4367458,45.135,2162,46.4973,,0.292795233
34.5155275,45.135,2300,47.9583,,0.31148429
34.59430919,45.135,1381,37.1618,,0.187026002
34.67309089,45.135,714,26.7208,,0.096695558
34.75187258,45.135,492,22.1811,,0.066630553
34.83065428,45.135,466,21.587,,0.063109426
34.90943598,45.135,436,20.8806,,0.059046587
34.98821767,45.135,398,19.9499,,0.053900325
35.06699937,45.135,371,19.2614,,0.05024377
35.14578106,45.135,424,20.5913,,0.057421452
35.22456276,45.135,397,19.9249,,0.053764897
35.30334446,45.135,383,19.5704,,0.051868906
35.38212615,45.135,419,20.4695,,0.056744312
35.46090785,45.135,425,20.6155,,0.05755688
35.53968954,45.135,454,21.3073,,0.06148429
35.61847124,45.135,472,21.7256,,0.063921993
35.69725294,45.135,581,24.1039,,0.07868364
35.77603463,45.135,565,23.7697,,0.076516793
35.85481633,45.135,666,25.807,,0.090195016
35.93359802,45.135,563,23.7276,,0.076245937
36.01237972,45.135,587,24.2281,,0.079496208
36.09116142,45.135,514,22.6716,,0.069609967
36.16994311,45.135,512,22.6274,,0.069339112
36.24872481,45.135,509,22.561,,0.068932828
36.3275065,45.135,563,23.7276,,0.076245937
36.4062882,45.135,838,28.9482,,0.113488624
36.4850699,45.135,1253,35.3977,,0.169691224
36.56385159,45.135,2547,50.4678,,0.344934995
36.64263329,45.135,6250,79.0569,,0.846424702
36.72141498,45.135,7116,84.3564,,0.963705309
36.80019668,45.135,4480,66.9328,,0.606717226
36.87897838,45.135,1852,43.0349,,0.250812568
36.95776007,45.135,915,30.249,,0.123916576
37.03654177,45.135,653,25.5539,,0.088434453
37.11532347,45.135,549,23.4307,,0.074349946
37.19410516,45.135,468,21.6333,,0.063380282
37.27288686,45.135,444,21.0713,,0.060130011
37.35166855,45.135,449,21.1896,,0.060807151
37.43045025,45.135,403,20.0749,,0.054577465
37.50923195,45.135,391,19.7737,,0.052952329
37.58801364,45.135,368,19.1833,,0.049837486
37.66679534,45.135,397,19.9249,,0.053764897
37.74557703,45.135,396,19.8997,,0.053629469
37.82435873,45.135,368,19.1833,,0.049837486
37.90314043,45.135,360,18.9737,,0.048754063
37.98192212,45.135,367,19.1572,,0.049702059
38.06070382,45.135,328,18.1108,,0.044420368
38.13948551,45.135,340,18.4391,,0.046045504
38.21826721,45.135,364,19.0788,,0.049295775
38.29704891,45.135,385,19.6214,,0.052139762
38.3758306,45.135,343,18.5203,,0.046451788
38.4546123,45.135,331,18.1934,,0.044826652
38.53339399,45.135,348,18.6548,,0.047128927
38.61217569,45.135,381,19.5192,,0.05159805
38.69095739,45.135,331,18.1934,,0.044826652
38.76973908,45.135,339,18.412,,0.045910076
38.84852078,45.135,351,18.735,,0.047535211
38.92730247,45.135,323,17.9722,,0.043743229
39.00608417,45.135,337,18.3576,,0.04563922
39.08486587,45.135,350,18.7083,,0.047399783
39.16364756,45.135,313,17.6918,,0.042388949
39.24242926,45.135,325,18.0278,,0.044014085
39.32121095,45.135,350,18.7083,,0.047399783
39.39999265,45.135,307,17.5214,,0.041576381
39.47877435,45.135,345,18.5742,,0.046722644
39.55755604,45.135,322,17.9444,,0.043607801
39.63633774,45.135,342,18.4932,,0.04631636
39.71511943,45.135,339,18.412,,0.045910076
39.79390113,45.135,334,18.2757,,0.045232936
39.87268283,45.135,382,19.5448,,0.051733478
39.95146452,45.135,370,19.2354,,0.050108342
40.03024622,45.135,398,19.9499,,0.053900325
40.10902792,45.135,380,19.4936,,0.051462622
40.18780961,45.135,336,18.3303,,0.045503792
40.26659131,45.135,328,18.1108,,0.044420368
40.345373,45.135,337,18.3576,,0.04563922
40.4241547,45.135,323,17.9722,,0.043743229
40.5029364,45.135,324,18,,0.043878657
40.58171809,45.135,327,18.0831,,0.04428494
40.66049979,45.135,311,17.6352,,0.042118093
40.73928148,45.135,354,18.8149,,0.047941495
40.81806318,45.135,336,18.3303,,0.045503792
40.89684488,45.135,310,17.6068,,0.041982665
40.97562657,45.135,326,18.0555,,0.044149512
41.05440827,45.135,338,18.3848,,0.045774648
41.13318996,45.135,303,17.4069,,0.04103467
41.21197166,45.135,361,19,,0.048889491
41.29075336,45.135,316,17.7764,,0.042795233
41.36953505,45.135,322,17.9444,,0.043607801
41.44831675,45.135,342,18.4932,,0.04631636
41.52709844,45.135,341,18.4662,,0.046180932
41.60588014,45.135,321,17.9165,,0.043472373
41.68466184,45.135,335,18.303,,0.045368364
41.76344353,45.135,335,18.303,,0.045368364
41.84222523,45.135,333,18.2483,,0.045097508
41.92100692,45.135,314,17.72,,0.042524377
41.99978862,45.135,328,18.1108,,0.044420368
42.07857032,45.135,336,18.3303,,0.045503792
42.15735201,45.135,295,17.1756,,0.039951246
42.23613371,45.135,331,18.1934,,0.044826652
42.3149154,45.135,356,18.868,,0.048212351
42.3936971,45.135,325,18.0278,,0.044014085
42.4724788,45.135,295,17.1756,,0.039951246
42.55126049,45.135,339,18.412,,0.045910076
42.63004219,45.135,339,18.412,,0.045910076
42.70882389,45.135,331,18.1934,,0.044826652
42.78760558,45.135,346,18.6011,,0.046858072
42.86638728,45.135,332,18.2209,,0.04496208
42.94516897,45.135,318,17.8326,,0.043066089
43.02395067,45.135,346,18.6011,,0.046858072
43.10273237,45.135,348,18.6548,,0.047128927
43.18151406,45.135,340,18.4391,,0.046045504
43.26029576,45.135,357,18.8944,,0.048347779
43.33907745,45.135,349,18.6815,,0.047264355
43.41785915,45.135,305,17.4642,,0.041305525
43.49664085,45.135,292,17.088,,0.039544962
43.57542254,45.135,299,17.2916,,0.040492958
43.65420424,45.135,322,17.9444,,0.043607801
43.73298593,45.135,305,17.4642,,0.041305525
43.81176763,45.135,308,17.5499,,0.041711809
43.89054933,45.135,289,17,,0.039138678
43.96933102,45.135,312,17.6635,,0.042253521
44.04811272,45.135,343,18.5203,,0.046451788
44.12689441,45.135,301,17.3494,,0.040763814
44.20567611,45.135,311,17.6352,,0.042118093
44.28445781,45.135,301,17.3494,,0.040763814
44.3632395,45.135,320,17.8885,,0.043336945
44.4420212,45.135,310,17.6068,,0.041982665
44.52080289,45.135,307,17.5214,,0.041576381
44.59958459,45.135,317,17.8045,,0.042930661
44.67836629,45.135,265,16.2788,,0.035888407
44.75714798,45.135,306,17.4929,,0.041440953
44.83592968,45.135,300,17.3205,,0.040628386
44.91471137,45.135,313,17.6918,,0.042388949
44.99349307,45.135,322,17.9444,,0.043607801
45.07227477,45.135,342,18.4932,,0.04631636
45.15105646,45.135,309,17.5784,,0.041847237
45.22983816,45.135,287,16.9411,,0.038867822
45.30861986,45.135,291,17.0587,,0.039409534
45.38740155,45.135,277,16.6433,,0.037513543
45.46618325,45.135,314,17.72,,0.042524377
45.54496494,45.135,263,16.2173,,0.035617551
45.62374664,45.135,332,18.2209,,0.04496208
45.70252834,45.135,296,17.2047,,0.040086674
45.78131003,45.135,332,18.2209,,0.04496208
45.86009173,45.135,318,17.8326,,0.043066089
45.93887342,45.135,271,16.4621,,0.036700975
46.01765512,45.135,284,16.8523,,0.038461538
46.09643682,45.135,281,16.7631,,0.038055255
46.17521851,45.135,280,16.7332,,0.037919827
46.25400021,45.135,298,17.2627,,0.04035753
46.3327819,45.135,318,17.8326,,0.043066089
46.4115636,45.135,309,17.5784,,0.041847237
46.4903453,45.135,298,17.2627,,0.04035753
46.56912699,45.135,307,17.5214,,0.041576381
46.64790869,45.135,272,16.4924,,0.036836403
46.72669038,45.135,293,17.1172,,0.03968039
46.80547208,45.135,306,17.4929,,0.041440953
46.88425378,45.135,320,17.8885,,0.043336945
46.96303547,45.135,306,17.4929,,0.041440953
47.04181717,45.135,314,17.72,,0.042524377
47.12059886,45.135,303,17.4069,,0.04103467
47.19938056,45.135,344,18.5472,,0.046587216
47.27816226,45.135,303,17.4069,,0.04103467
47.35694395,45.135,296,17.2047,,0.040086674
47.43572565,45.135,324,18,,0.043878657
47.51450734,45.135,312,17.6635,,0.042253521
47.59328904,45.135,327,18.0831,,0.04428494
47.67207074,45.135,401,20.025,,0.054306609
47.75085243,45.135,574,23.9583,,0.077735645
47.82963413,45.135,839,28.9655,,0.113624052
47.90841582,45.135,1033,32.1403,,0.139897075
47.98719752,45.135,849,29.1376,,0.114978332
48.06597922,45.135,607,24.6374,,0.082204767
48.14476091,45.135,393,19.8242,,0.053223185
48.22354261,45.135,356,18.868,,0.048212351
48.30232431,45.135,306,17.4929,,0.041440953
48.381106,45.135,359,18.9473,,0.048618635
48.4598877,45.135,290,17.0294,,0.039274106
48.53866939,45.135,338,18.3848,,0.045774648
48.61745109,45.135,301,17.3494,,0.040763814
48.69623279,45.135,293,17.1172,,0.03968039
48.77501448,45.135,305,17.4642,,0.041305525
48.85379618,45.135,269,16.4012,,0.036430119
48.93257787,45.135,302,17.3781,,0.040899242
49.01135957,45.135,282,16.7929,,0.038190683
49.09014127,45.135,297,17.2337,,0.040222102
49.16892296,45.135,291,17.0587,,0.039409534
49.24770466,45.135,309,17.5784,,0.041847237
49.32648635,45.135,283,16.8226,,0.038326111
49.40526805,45.135,286,16.9115,,0.038732394
49.48404975,45.135,294,17.1464,,0.039815818
49.56283144,45.135,296,17.2047,,0.040086674
49.64161314,45.135,255,15.9687,,0.034534128
49.72039483,45.135,298,17.2627,,0.04035753
49.79917653,45.135,252,15.8745,,0.034127844
49.87795823,45.135,270,16.4317,,0.036565547
49.95673992,45.135,311,17.6352,,0.042118093
50.03552162,45.135,284,16.8523,,0.038461538
50.11430331,45.135,275,16.5831,,0.037242687
50.19308501,45.135,261,16.1555,,0.035346696
50.27186671,45.135,262,16.1864,,0.035482124
50.3506484,45.135,288,16.9706,,0.03900325
50.4294301,45.135,283,16.8226,,0.038326111
50.50821179,45.135,251,15.843,,0.033992416
50.58699349,45.135,260,16.1245,,0.035211268
50.66577519,45.135,270,16.4317,,0.036565547
50.74455688,45.135,284,16.8523,,0.038461538
50.82333858,45.135,275,16.5831,,0.037242687
50.90212028,45.135,281,16.7631,,0.038055255
50.98090197,45.135,263,16.2173,,0.035617551
51.05968367,45.135,252,15.8745,,0.034127844
51.13846536,45.135,297,17.2337,,0.040222102
51.21724706,45.135,301,17.3494,,0.040763814
51.29602876,45.135,253,15.906,,0.034263272
51.37481045,45.135,273,16.5227,,0.036971831
51.45359215,45.135,285,16.8819,,0.038596966
51.53237384,45.135,280,16.7332,,0.037919827
51.61115554,45.135,277,16.6433,,0.037513543
51.68993724,45.135,267,16.3401,,0.036159263
51.76871893,45.135,250,15.8114,,0.033856988
51.84750063,45.135,284,16.8523,,0.038461538
51.92628232,45.135,288,16.9706,,0.03900325
52.00506402,45.135,290,17.0294,,0.039274106
52.08384572,45.135,265,16.2788,,0.035888407
52.16262741,45.135,285,16.8819,,0.038596966
52.24140911,45.135,265,16.2788,,0.035888407
52.3201908,45.135,251,15.843,,0.033992416
52.3989725,45.135,277,16.6433,,0.037513543
52.4777542,45.135,262,16.1864,,0.035482124
52.55653589,45.135,258,16.0624,,0.034940412
52.63531759,45.135,269,16.4012,,0.036430119
52.71409928,45.135,258,16.0624,,0.034940412
52.79288098,45.135,268,16.3707,,0.036294691
52.87166268,45.135,270,16.4317,,0.036565547
52.95044437,45.135,251,15.843,,0.033992416
53.02922607,45.135,275,16.5831,,0.037242687
53.10800776,45.135,262,16.1864,,0.035482124
53.18678946,45.135,259,16.0935,,0.03507584
53.26557116,45.135,260,16.1245,,0.035211268
53.34435285,45.135,242,15.5563,,0.032773564
53.42313455,45.135,206,14.3527,,0.027898158
53.50191625,45.135,240,15.4919,,0.032502709
53.58069794,45.135,287,16.9411,,0.038867822
53.65947964,45.135,228,15.0997,,0.030877573
53.73826133,45.135,288,16.9706,,0.03900325
53.81704303,45.135,261,16.1555,,0.035346696
53.89582473,45.135,286,16.9115,,0.038732394
53.97460642,45.135,277,16.6433,,0.037513543
54.05338812,45.135,280,16.7332,,0.037919827
54.13216981,45.135,259,16.0935,,0.03507584
54.21095151,45.135,290,17.0294,,0.039274106
54.28973321,45.135,248,15.748,,0.033586132
54.3685149,45.135,284,16.8523,,0.038461538
54.4472966,45.135,276,16.6132,,0.037378115
54.52607829,45.135,303,17.4069,,0.04103467
54.60485999,45.135,344,18.5472,,0.046587216
54.68364169,45.135,354,18.8149,,0.047941495
54.76242338,45.135,370,19.2354,,0.050108342
54.84120508,45.135,318,17.8326,,0.043066089
54.91998677,45.135,335,18.303,,0.045368364
54.99876847,45.135,286,16.9115,,0.038732394
55.07755017,45.135,276,16.6132,,0.037378115
55.15633186,45.135,245,15.6525,,0.033179848
55.23511356,45.135,248,15.748,,0.033586132
55.31389525,45.135,271,16.4621,,0.036700975
55.39267695,45.135,250,15.8114,,0.033856988
55.47145865,45.135,238,15.4272,,0.032231853
55.55024034,45.135,262,16.1864,,0.035482124
55.62902204,45.135,247,15.7162,,0.033450704
55.70780373,45.135,255,15.9687,,0.034534128
55.78658543,45.135,227,15.0665,,0.030742145
55.86536713,45.135,250,15.8114,,0.033856988
55.94414882,45.135,234,15.2971,,0.031690141
56.02293052,45.135,237,15.3948,,0.032096425
56.10171221,45.135,223,14.9332,,0.030200433
56.18049391,45.135,274,16.5529,,0.037107259
56.25927561,45.135,237,15.3948,,0.032096425
56.3380573,45.135,237,15.3948,,0.032096425
56.416839,45.135,233,15.2643,,0.031554713
56.4956207,45.135,246,15.6844,,0.033315276
56.57440239,45.135,245,15.6525,,0.033179848
56.65318409,45.135,245,15.6525,,0.033179848
56.73196578,45.135,274,16.5529,,0.037107259
56.81074748,45.135,266,16.3095,,0.036023835
56.88952918,45.135,225,15,,0.030471289
56.96831087,45.135,223,14.9332,,0.030200433
57.04709257,45.135,269,16.4012,,0.036430119
57.12587426,45.135,288,16.9706,,0.03900325
57.20465596,45.135,315,17.7482,,0.042659805
57.28343766,45.135,394,19.8494,,0.053358613
57.36221935,45.135,687,26.2107,,0.093039003
57.44100105,45.135,1052,32.4345,,0.142470206
57.51978274,45.135,785,28.0179,,0.106310943
57.59856444,45.135,726,26.9444,,0.098320693
57.67734614,45.135,481,21.9317,,0.065140845
57.75612783,45.135,342,18.4932,,0.04631636
57.83490953,45.135,287,16.9411,,0.038867822
57.91369122,45.135,265,16.2788,,0.035888407
57.99247292,45.135,297,17.2337,,0.040222102
58.07125462,45.135,234,15.2971,,0.031690141
58.15003631,45.135,256,16,,0.034669556
58.22881801,45.135,256,16,,0.034669556
58.3075997,45.135,238,15.4272,,0.032231853
58.3863814,45.135,206,14.3527,,0.027898158
58.4651631,45.135,276,16.6132,,0.037378115
58.54394479,45.135,224,14.9666,,0.030335861
58.62272649,45.135,279,16.7033,,0.037784399
58.70150818,45.135,237,15.3948,,0.032096425
58.78028988,45.135,274,16.5529,,0.037107259
58.85907158,45.135,209,14.4568,,0.028304442
58.93785327,45.135,240,15.4919,,0.032502709
59.01663497,45.135,230,15.1658,,0.031148429
59.09541667,45.135,249,15.7797,,0.03372156
59.17419836,45.135,215,14.6629,,0.02911701
59.25298006,45.135,220,14.8324,,0.02979415
59.33176175,45.135,221,14.8661,,0.029929577
59.41054345,45.135,220,14.8324,,0.02979415
59.48932515,45.135,247,15.7162,,0.033450704
59.56810684,45.135,214,14.6287,,0.028981582
59.64688854,45.135,234,15.2971,,0.031690141
59.72567023,45.135,235,15.3297,,0.031825569
59.80445193,45.135,233,15.2643,,0.031554713
59.88323363,45.135,198,14.0712,,0.026814735
59.96201532,45.135,220,14.8324,,0.02979415
60.04079702,45.135,223,14.9332,,0.030200433
60.11957871,45.135,238,15.4272,,0.032231853
60.19836041,45.135,226,15.0333,,0.030606717
60.27714211,45.135,218,14.7648,,0.029523294
60.3559238,45.135,210,14.4914,,0.02843987
60.4347055,45.135,201,14.1774,,0.027221018
60.51348719,45.135,234,15.2971,,0.031690141
60.59226889,45.135,223,14.9332,,0.030200433
60.67105059,45.135,238,15.4272,,0.032231853
60.74983228,45.135,253,15.906,,0.034263272
60.82861398,45.135,207,14.3875,,0.028033586
60.90739567,45.135,230,15.1658,,0.031148429
60.98617737,45.135,208,14.4222,,0.028169014
61.06495907,45.135,236,15.3623,,0.031960997
61.14374076,45.135,243,15.5885,,0.032908992
61.22252246,45.135,252,15.8745,,0.034127844
61.30130415,45.135,232,15.2315,,0.031419285
61.38008585,45.135,232,15.2315,,0.031419285
61.45886755,45.135,235,15.3297,,0.031825569
61.53764924,45.135,222,14.8997,,0.030065005
61.61643094,45.135,255,15.9687,,0.034534128
61.69521264,45.135,241,15.5242,,0.032638137
61.77399433,45.135,233,15.2643,,0.031554713
61.85277603,45.135,225,15,,0.030471289
61.93155772,45.135,218,14.7648,,0.029523294
62.01033942,45.135,240,15.4919,,0.032502709
62.08912112,45.135,222,14.8997,,0.030065005
62.16790281,45.135,209,14.4568,,0.028304442
62.24668451,45.135,219,14.7986,,0.029658722
62.3254662,45.135,245,15.6525,,0.033179848
62.4042479,45.135,239,15.4596,,0.032367281
62.4830296,45.135,273,16.5227,,0.036971831
62.56181129,45.135,240,15.4919,,0.032502709
62.64059299,45.135,253,15.906,,0.034263272
62.71937468,45.135,261,16.1555,,0.035346696
62.79815638,45.135,276,16.6132,,0.037378115
62.87693808,45.135,315,17.7482,,0.042659805
62.95571977,45.135,371,19.2614,,0.05024377
63.03450147,45.135,566,23.7908,,0.076652221
63.11328316,45.135,791,28.1247,,0.10712351
63.19206486,45.135,781,27.9464,,0.105769231
63.27084656,45.135,674,25.9615,,0.09127844
63.34962825,45.135,537,23.1733,,0.07272481
63.42840995,45.135,347,18.6279,,0.046993499
63.50719164,45.135,316,17.7764,,0.042795233
63.58597334,45.135,257,16.0312,,0.034804984
63.66475504,45.135,219,14.7986,,0.029658722
63.74353673,45.135,226,15.0333,,0.030606717
63.82231843,45.135,215,14.6629,,0.02911701
63.90110012,45.135,208,14.4222,,0.028169014
63.97988182,45.135,212,14.5602,,0.028710726
64.05866352,45.135,222,14.8997,,0.030065005
64.13744521,45.135,192,13.8564,,0.026002167
64.21622691,45.135,199,14.1067,,0.026950163
64.2950086,45.135,228,15.0997,,0.030877573
64.3737903,45.135,209,14.4568,,0.028304442
64.452572,45.135,221,14.8661,,0.029929577
64.53135369,45.135,219,14.7986,,0.029658722
64.61013539,45.135,247,15.7162,,0.033450704
64.68891709,45.135,192,13.8564,,0.026002167
64.76769878,45.135,185,13.6015,,0.025054171
64.84648048,45.135,191,13.8203,,0.025866739
64.92526217,45.135,181,13.4536,,0.024512459
65.00404387,45.135,209,14.4568,,0.028304442
65.08282557,45.135,199,14.1067,,0.026950163
65.16160726,45.135,222,14.8997,,0.030065005
65.24038896,45.135,213,14.5945,,0.028846154
65.31917065,45.135,209,14.4568,,0.028304442
65.39795235,45.135,204,14.2829,,0.027627302
65.47673405,45.135,226,15.0333,,0.030606717
65.55551574,45.135,214,14.6287,,0.028981582
65.63429744,45.135,183,13.5277,,0.024783315
65.71307913,45.135,230,15.1658,,0.031148429
65.79186083,45.135,219,14.7986,,0.029658722
65.87064253,45.135,214,14.6287,,0.028981582
65.94942422,45.135,224,14.9666,,0.030335861
66.02820592,45.135,211,14.5258,,0.028575298
66.10698761,45.135,213,14.5945,,0.028846154
66.18576931,45.135,201,14.1774,,0.027221018
66.26455101,45.135,209,14.4568,,0.028304442
66.3433327,45.135,207,14.3875,,0.028033586
66.4221144,45.135,224,14.9666,,0.030335861
66.50089609,45.135,172,13.1149,,0.023293608
66.57967779,45.135,184,13.5647,,0.024918743
66.65845949,45.135,211,14.5258,,0.028575298
66.73724118,45.135,183,13.5277,,0.024783315
66.81602288,45.135,219,14.7986,,0.029658722
66.89480457,45.135,211,14.5258,,0.028575298
66.97358627,45.135,219,14.7986,,0.029658722
67.05236797,45.135,191,13.8203,,0.025866739
67.13114966,45.135,190,13.784,,0.025731311
67.20993136,45.135,220,14.8324,,0.02979415
67.28871306,45.135,261,16.1555,,0.035346696
67.36749475,45.135,257,16.0312,,0.034804984
67.44627645,45.135,279,16.7033,,0.037784399
67.52505814,45.135,266,16.3095,,0.036023835
67.60383984,45.135,204,14.2829,,0.027627302
67.68262154,45.135,206,14.3527,,0.027898158
67.76140323,45.135,234,15.2971,,0.031690141
67.84018493,45.135,189,13.7477,,0.025595883
67.91896662,45.135,219,14.7986,,0.029658722
67.99774832,45.135,220,14.8324,,0.02979415
68.07653002,45.135,218,14.7648,,0.029523294
68.15531171,45.135,205,14.3178,,0.02776273
68.23409341,45.135,228,15.0997,,0.030877573
68.3128751,45.135,206,14.3527,,0.027898158
68.3916568,45.135,226,15.0333,,0.030606717
68.4704385,45.135,291,17.0587,,0.039409534
68.54922019,45.135,395,19.8746,,0.053494041
68.62800189,45.135,595,24.3926,,0.080579632
68.70678358,45.135,810,28.4605,,0.109696641
68.78556528,45.135,631,25.1197,,0.085455038
68.86434698,45.135,601,24.5153,,0.081392199
68.94312867,45.135,450,21.2132,,0.060942579
69.02191037,45.135,321,17.9165,,0.043472373
69.10069206,45.135,280,16.7332,,0.037919827
69.17947376,45.135,237,15.3948,,0.032096425
69.25825546,45.135,228,15.0997,,0.030877573
69.33703715,45.135,217,14.7309,,0.029387866
69.41581885,45.135,214,14.6287,,0.028981582
69.49460054,45.135,255,15.9687,,0.034534128
69.57338224,45.135,201,14.1774,,0.027221018
69.65216394,45.135,220,14.8324,,0.02979415
69.73094563,45.135,229,15.1327,,0.031013001
69.80972733,45.135,224,14.9666,,0.030335861
69.88850903,45.135,296,17.2047,,0.040086674
69.96729072,45.135,398,19.9499,,0.053900325
70.04607242,45.135,604,24.5764,,0.081798483
70.12485411,45.135,527,22.9565,,0.071370531
70.20363581,45.135,397,19.9249,,0.053764897
70.28241751,45.135,425,20.6155,,0.05755688
70.3611992,45.135,316,17.7764,,0.042795233
70.4399809,45.135,247,15.7162,,0.033450704
70.51876259,45.135,211,14.5258,,0.028575298
70.59754429,45.135,202,14.2127,,0.027356446
70.67632599,45.135,185,13.6015,,0.025054171
70.75510768,45.135,187,13.6748,,0.025325027
70.83388938,45.135,198,14.0712,,0.026814735
70.91267107,45.135,192,13.8564,,0.026002167
70.99145277,45.135,214,14.6287,,0.028981582
71.07023447,45.135,191,13.8203,,0.025866739
71.14901616,45.135,191,13.8203,,0.025866739
71.22779786,45.135,194,13.9284,,0.026273023
71.30657955,45.135,193,13.8924,,0.026137595
71.38536125,45.135,192,13.8564,,0.026002167
71.46414295,45.135,176,13.2665,,0.02383532
71.54292464,45.135,198,14.0712,,0.026814735
71.62170634,45.135,214,14.6287,,0.028981582
71.70048803,45.135,186,13.6382,,0.025189599
71.77926973,45.135,189,13.7477,,0.025595883
71.85805143,45.135,196,14,,0.026543879
71.93683312,45.135,175,13.2288,,0.023699892
72.01561482,45.135,218,14.7648,,0.029523294
72.09439651,45.135,172,13.1149,,0.023293608
72.17317821,45.135,185,13.6015,,0.025054171
72.25195991,45.135,189,13.7477,,0.025595883
72.3307416,45.135,169,13,,0.022887324
72.4095233,45.135,201,14.1774,,0.027221018
72.488305,45.135,234,15.2971,,0.031690141
72.56708669,45.135,258,16.0624,,0.034940412
72.64586839,45.135,234,15.2971,,0.031690141
72.72465008,45.135,220,14.8324,,0.02979415
72.80343178,45.135,218,14.7648,,0.029523294
72.88221348,45.135,227,15.0665,,0.030742145
72.96099517,45.135,204,14.2829,,0.027627302
73.03977687,45.135,179,13.3791,,0.024241603
73.11855856,45.135,167,12.9228,,0.022616468
73.19734026,45.135,200,14.1421,,0.02708559
73.27612196,45.135,187,13.6748,,0.025325027
73.35490365,45.135,174,13.1909,,0.023564464
73.43368535,45.135,161,12.6886,,0.0218039
73.51246704,45.135,175,13.2288,,0.023699892
73.59124874,45.135,216,14.6969,,0.029252438
73.67003044,45.135,155,12.4499,,0.020991333
73.74881213,45.135,151,12.2882,,0.020449621
73.82759383,45.135,166,12.8841,,0.02248104
73.90637552,45.135,166,12.8841,,0.02248104
73.98515722,45.135,178,13.3417,,0.024106176
74.06393892,45.135,183,13.5277,,0.024783315
74.14272061,45.135,179,13.3791,,0.024241603
74.22150231,45.135,160,12.6491,,0.021668472
74.300284,45.135,176,13.2665,,0.02383532
74.3790657,45.135,208,14.4222,,0.028169014
74.4578474,45.135,199,14.1067,,0.026950163
74.53662909,45.135,193,13.8924,,0.026137595
74.61541079,45.135,186,13.6382,,0.025189599
74.69419248,45.135,190,13.784,,0.025731311
74.77297418,45.135,179,13.3791,,0.024241603
74.85175588,45.135,168,12.9615,,0.022751896
74.93053757,45.135,169,13,,0.022887324
75.00931927,45.135,182,13.4907,,0.024647887
75.08810096,45.135,169,13,,0.022887324
75.16688266,45.135,173,13.1529,,0.023429036
75.24566436,45.135,177,13.3041,,0.023970748
75.32444605,45.135,189,13.7477,,0.025595883
75.40322775,45.135,178,13.3417,,0.024106176
75.48200945,45.135,178,13.3417,,0.024106176
75.56079114,45.135,177,13.3041,,0.023970748
75.63957284,45.135,185,13.6015,,0.025054171
75.71835453,45.135,156,12.49,,0.021126761
75.79713623,45.135,197,14.0357,,0.026679307
75.87591793,45.135,178,13.3417,,0.024106176
75.95469962,45.135,168,12.9615,,0.022751896
76.03348132,45.135,157,12.53,,0.021262189
76.11226301,45.135,174,13.1909,,0.023564464
76.19104471,45.135,181,13.4536,,0.024512459
76.26982641,45.135,179,13.3791,,0.024241603
76.3486081,45.135,162,12.7279,,0.021939328
76.4273898,45.135,197,14.0357,,0.026679307
76.50617149,45.135,160,12.6491,,0.021668472
76.58495319,45.135,149,12.2066,,0.020178765
76.66373489,45.135,206,14.3527,,0.027898158
76.74251658,45.135,172,13.1149,,0.023293608
76.82129828,45.135,173,13.1529,,0.023429036
76.90007997,45.135,159,12.6095,,0.021533044
76.97886167,45.135,173,13.1529,,0.023429036
77.05764337,45.135,149,12.2066,,0.020178765
77.13642506,45.135,145,12.0416,,0.019637053
77.21520676,45.135,172,13.1149,,0.023293608
77.29398845,45.135,173,13.1529,,0.023429036
77.37277015,45.135,137,11.7047,,0.018553629
77.45155185,45.135,179,13.3791,,0.024241603
77.53033354,45.135,171,13.0767,,0.02315818
77.60911524,45.135,184,13.5647,,0.024918743
77.68789693,45.135,173,13.1529,,0.023429036
77.76667863,45.135,191,13.8203,,0.025866739
77.84546033,45.135,268,16.3707,,0.036294691
77.92424202,45.135,255,15.9687,,0.034534128
78.00302372,45.135,207,14.3875,,0.028033586
78.08180542,45.135,236,15.3623,,0.031960997
78.16058711,45.135,183,13.5277,,0.024783315
78.23936881,45.135,191,13.8203,,0.025866739
78.3181505,45.135,189,13.7477,,0.025595883
78.3969322,45.135,196,14,,0.026543879
78.4757139,45.135,183,13.5277,,0.024783315
78.55449559,45.135,153,12.3693,,0.020720477
78.63327729,45.135,172,13.1149,,0.023293608
78.71205898,45.135,163,12.7671,,0.022074756
78.79084068,45.135,178,13.3417,,0.024106176
78.86962238,45.135,167,12.9228,,0.022616468
78.94840407,45.135,169,13,,0.022887324
79.02718577,45.135,169,13,,0.022887324
79.10596746,45.135,175,13.2288,,0.023699892
79.18474916,45.135,138,11.7473,,0.018689057
79.26353086,45.135,154,12.4097,,0.020855905
79.34231255,45.135,172,13.1149,,0.023293608
79.42109425,45.135,184,13.5647,,0.024918743
79.49987594,45.135,157,12.53,,0.021262189
79.57865764,45.135,182,13.4907,,0.024647887
79.65743934,45.135,184,13.5647,,0.024918743
79.73622103,45.135,154,12.4097,,0.020855905
79.81500273,45.135,168,12.9615,,0.022751896
79.89378442,45.135,172,13.1149,,0.023293608
79.97256612,45.135,175,13.2288,,0.023699892