File: sheets/80W.csv
[Measurement conditions],,,,,
Sample identification,,,,,
Comment - 1,"Configuration=Reflection-transmission spinner, Owner=User-1, Creation date=12/4/2012 10:13:13 AM",,,,
Comment - 2,Goniometer=Theta/Theta; Minimum step size 2Theta:0.0001; Minimum step size Omega:0.0001,,,,
Comment - 3,Sample stage=Reflection-transmission spinner; Minimum step size Phi:0.1,,,,
Comment - 4,Diffractometer system=EMPYREAN,,,,
Comment - 5,"Measurement program=C:\PANalytical\Data Collector\Programs\PI Lorenzo Mangolini\BrandonWagner_Mg.xrdmp, Identifier={9EE36770-7A59-4EAA-85D0-90E43AFBFC91}",,,,
Anode material,Cu,,,,
K-Alpha1 wavelength,1.540598,,,,
K-Alpha2 wavelength,1.544426,,,,
Ratio K-Alpha2/K-Alpha1,0.5,,,,
Divergence slit,Fixed,0.76mm,,,
Monochromator used,NO,,,,
Generator voltage,45,,,,
Tube current,40,,,,
File date and time,4/5/2023 15:56,,,,
Unit cell,,,,,
h k l, 0 0 0,,,,
Scan axis,Gonio,,,,
Scan range,20,79.99226154,,,
Scan step size,0.0393908,,,,
No. of points,1523,,,,
Scan type,CONTINUOUS,,,,
Phi,184.9,,,,
Time per step,45.135,,,,
[Scan points],,,,,
Angle, TimePerStep, Intensity, ESD,,
20.01969542,45.135,490,22.1359,9608,0.050999167
20.09847712,45.135,497,22.2935,,0.051727727
20.17725881,45.135,530,23.0217,,0.055162365
20.25604051,45.135,514,22.6716,,0.053497086
20.3348222,45.135,496,22.2711,,0.051623647
20.4136039,45.135,510,22.5832,,0.053080766
20.4923856,45.135,536,23.1517,,0.055786844
20.57116729,45.135,552,23.4947,,0.057452123
20.64994899,45.135,503,22.4277,,0.052352206
20.72873069,45.135,446,21.1187,,0.04641965
20.80751238,45.135,513,22.6495,,0.053393006
20.88629408,45.135,503,22.4277,,0.052352206
20.96507577,45.135,509,22.561,,0.052976686
21.04385747,45.135,507,22.5167,,0.052768526
21.12263917,45.135,509,22.561,,0.052976686
21.20142086,45.135,512,22.6274,,0.053288926
21.28020256,45.135,491,22.1585,,0.051103247
21.35898425,45.135,475,21.7945,,0.049437968
21.43776595,45.135,514,22.6716,,0.053497086
21.51654765,45.135,506,22.4944,,0.052664446
21.59532934,45.135,484,22,,0.050374688
21.67411104,45.135,487,22.0681,,0.050686928
21.75289273,45.135,525,22.9129,,0.054641965
21.83167443,45.135,533,23.0868,,0.055474604
21.91045613,45.135,468,21.6333,,0.048709409
21.98923782,45.135,472,21.7256,,0.049125729
22.06801952,45.135,476,21.8174,,0.049542048
22.14680121,45.135,433,20.8087,,0.045066611
22.22558291,45.135,510,22.5832,,0.053080766
22.30436461,45.135,494,22.2261,,0.051415487
22.3831463,45.135,491,22.1585,,0.051103247
22.461928,45.135,509,22.561,,0.052976686
22.54070969,45.135,446,21.1187,,0.04641965
22.61949139,45.135,414,20.347,,0.043089092
22.69827309,45.135,442,21.0238,,0.046003331
22.77705478,45.135,502,22.4054,,0.052248127
22.85583648,45.135,462,21.4942,,0.048084929
22.93461817,45.135,459,21.4243,,0.047772689
23.01339987,45.135,453,21.2838,,0.04714821
23.09218157,45.135,498,22.3159,,0.051831807
23.17096326,45.135,438,20.9284,,0.045587011
23.24974496,45.135,414,20.347,,0.043089092
23.32852665,45.135,467,21.6102,,0.048605329
23.40730835,45.135,477,21.8403,,0.049646128
23.48609005,45.135,450,21.2132,,0.04683597
23.56487174,45.135,434,20.8327,,0.045170691
23.64365344,45.135,400,20,,0.041631973
23.72243514,45.135,453,21.2838,,0.04714821
23.80121683,45.135,463,21.5174,,0.048189009
23.87999853,45.135,426,20.6398,,0.044338052
23.95878022,45.135,470,21.6795,,0.048917569
24.03756192,45.135,430,20.7364,,0.044754371
24.11634362,45.135,425,20.6155,,0.044233972
24.19512531,45.135,479,21.8861,,0.049854288
24.27390701,45.135,400,20,,0.041631973
24.3526887,45.135,405,20.1246,,0.042152373
24.4314704,45.135,448,21.166,,0.04662781
24.5102521,45.135,449,21.1896,,0.04673189
24.58903379,45.135,421,20.5183,,0.043817652
24.66781549,45.135,456,21.3542,,0.04746045
24.74659718,45.135,439,20.9523,,0.045691091
24.82537888,45.135,420,20.4939,,0.043713572
24.90416058,45.135,376,19.3907,,0.039134055
24.98294227,45.135,388,19.6977,,0.040383014
25.06172397,45.135,428,20.6882,,0.044546211
25.14050566,45.135,407,20.1742,,0.042360533
25.21928736,45.135,444,21.0713,,0.04621149
25.29806906,45.135,402,20.0499,,0.041840133
25.37685075,45.135,432,20.7846,,0.044962531
25.45563245,45.135,400,20,,0.041631973
25.53441414,45.135,422,20.5426,,0.043921732
25.61319584,45.135,416,20.3961,,0.043297252
25.69197754,45.135,444,21.0713,,0.04621149
25.77075923,45.135,415,20.3715,,0.043193172
25.84954093,45.135,472,21.7256,,0.049125729
25.92832262,45.135,431,20.7605,,0.044858451
26.00710432,45.135,437,20.9045,,0.045482931
26.08588602,45.135,401,20.025,,0.041736053
26.16466771,45.135,388,19.6977,,0.040383014
26.24344941,45.135,419,20.4695,,0.043609492
26.32223111,45.135,421,20.5183,,0.043817652
26.4010128,45.135,433,20.8087,,0.045066611
26.4797945,45.135,438,20.9284,,0.045587011
26.55857619,45.135,362,19.0263,,0.037676936
26.63735789,45.135,417,20.4206,,0.043401332
26.71613959,45.135,363,19.0526,,0.037781016
26.79492128,45.135,386,19.6469,,0.040174854
26.87370298,45.135,453,21.2838,,0.04714821
26.95248467,45.135,403,20.0749,,0.041944213
27.03126637,45.135,392,19.799,,0.040799334
27.11004807,45.135,453,21.2838,,0.04714821
27.18882976,45.135,403,20.0749,,0.041944213
27.26761146,45.135,412,20.2978,,0.042880933
27.34639315,45.135,444,21.0713,,0.04621149
27.42517485,45.135,439,20.9523,,0.045691091
27.50395655,45.135,435,20.8567,,0.045274771
27.58273824,45.135,463,21.5174,,0.048189009
27.66151994,45.135,497,22.2935,,0.051727727
27.74030163,45.135,496,22.2711,,0.051623647
27.81908333,45.135,560,23.6643,,0.058284763
27.89786503,45.135,729,27,,0.075874271
27.97664672,45.135,822,28.6705,,0.085553705
28.05542842,45.135,854,29.2233,,0.088884263
28.13421011,45.135,670,25.8844,,0.069733555
28.21299181,45.135,610,24.6982,,0.063488759
28.29177351,45.135,472,21.7256,,0.049125729
28.3705552,45.135,519,22.7816,,0.054017485
28.4493369,45.135,447,21.1424,,0.04652373
28.52811859,45.135,445,21.095,,0.04631557
28.60690029,45.135,437,20.9045,,0.045482931
28.68568199,45.135,382,19.5448,,0.039758535
28.76446368,45.135,416,20.3961,,0.043297252
28.84324538,45.135,389,19.7231,,0.040487094
28.92202708,45.135,394,19.8494,,0.041007494
29.00080877,45.135,426,20.6398,,0.044338052
29.07959047,45.135,424,20.5913,,0.044129892
29.15837216,45.135,371,19.2614,,0.038613655
29.23715386,45.135,377,19.4165,,0.039238135
29.31593556,45.135,356,18.868,,0.037052456
29.39471725,45.135,364,19.0788,,0.037885096
29.47349895,45.135,364,19.0788,,0.037885096
29.55228064,45.135,403,20.0749,,0.041944213
29.63106234,45.135,387,19.6723,,0.040278934
29.70984404,45.135,398,19.9499,,0.041423813
29.78862573,45.135,362,19.0263,,0.037676936
29.86740743,45.135,371,19.2614,,0.038613655
29.94618912,45.135,414,20.347,,0.043089092
30.02497082,45.135,380,19.4936,,0.039550375
30.10375252,45.135,374,19.3391,,0.038925895
30.18253421,45.135,387,19.6723,,0.040278934
30.26131591,45.135,376,19.3907,,0.039134055
30.3400976,45.135,375,19.3649,,0.039029975
30.4188793,45.135,375,19.3649,,0.039029975
30.497661,45.135,385,19.6214,,0.040070774
30.57644269,45.135,395,19.8746,,0.041111574
30.65522439,45.135,371,19.2614,,0.038613655
30.73400608,45.135,356,18.868,,0.037052456
30.81278778,45.135,345,18.5742,,0.035907577
30.89156948,45.135,374,19.3391,,0.038925895
30.97035117,45.135,374,19.3391,,0.038925895
31.04913287,45.135,425,20.6155,,0.044233972
31.12791456,45.135,419,20.4695,,0.043609492
31.20669626,45.135,365,19.105,,0.037989176
31.28547796,45.135,420,20.4939,,0.043713572
31.36425965,45.135,410,20.2485,,0.042672773
31.44304135,45.135,404,20.0998,,0.042048293
31.52182304,45.135,375,19.3649,,0.039029975
31.60060474,45.135,407,20.1742,,0.042360533
31.67938644,45.135,390,19.7484,,0.040591174
31.75816813,45.135,390,19.7484,,0.040591174
31.83694983,45.135,408,20.199,,0.042464613
31.91573153,45.135,440,20.9762,,0.045795171
31.99451322,45.135,488,22.0907,,0.050791007
32.07329492,45.135,629,25.0799,,0.065466278
32.15207661,45.135,1432,37.8418,,0.149042465
32.23085831,45.135,2740,52.345,,0.285179017
32.30964001,45.135,2745,52.3927,,0.285699417
32.3884217,45.135,1496,38.6782,,0.15570358
32.4672034,45.135,688,26.2298,,0.071606994
32.54598509,45.135,522,22.8473,,0.054329725
32.62476679,45.135,488,22.0907,,0.050791007
32.70354849,45.135,422,20.5426,,0.043921732
32.78233018,45.135,468,21.6333,,0.048709409
32.86111188,45.135,398,19.9499,,0.041423813
32.93989357,45.135,415,20.3715,,0.043193172
33.01867527,45.135,451,21.2368,,0.04694005
33.09745697,45.135,456,21.3542,,0.04746045
33.17623866,45.135,408,20.199,,0.042464613
33.25502036,45.135,422,20.5426,,0.043921732
33.33380205,45.135,413,20.3224,,0.042985012
33.41258375,45.135,381,19.5192,,0.039654455
33.49136545,45.135,372,19.2873,,0.038717735
33.57014714,45.135,399,19.975,,0.041527893
33.64892884,45.135,415,20.3715,,0.043193172
33.72771053,45.135,418,20.445,,0.043505412
33.80649223,45.135,399,19.975,,0.041527893
33.88527393,45.135,403,20.0749,,0.041944213
33.96405562,45.135,413,20.3224,,0.042985012
34.04283732,45.135,448,21.166,,0.04662781
34.12161901,45.135,445,21.095,,0.04631557
34.20040071,45.135,514,22.6716,,0.053497086
34.27918241,45.135,665,25.7876,,0.069213156
34.3579641,45.135,1328,36.4417,,0.138218152
34.4367458,45.135,2558,50.5767,,0.26623647
34.5155275,45.135,2993,54.7083,,0.311511241
34.59430919,45.135,1939,44.0341,,0.201810991
34.67309089,45.135,950,30.8221,,0.098875937
34.75187258,45.135,599,24.4745,,0.06234388
34.83065428,45.135,499,22.3383,,0.051935887
34.90943598,45.135,470,21.6795,,0.048917569
34.98821767,45.135,481,21.9317,,0.050062448
35.06699937,45.135,431,20.7605,,0.044858451
35.14578106,45.135,421,20.5183,,0.043817652
35.22456276,45.135,435,20.8567,,0.045274771
35.30334446,45.135,454,21.3073,,0.04725229
35.38212615,45.135,444,21.0713,,0.04621149
35.46090785,45.135,476,21.8174,,0.049542048
35.53968954,45.135,519,22.7816,,0.054017485
35.61847124,45.135,575,23.9792,,0.059845962
35.69725294,45.135,664,25.7682,,0.069109076
35.77603463,45.135,839,28.9655,,0.087323064
35.85481633,45.135,899,29.9833,,0.09356786
35.93359802,45.135,812,28.4956,,0.084512906
36.01237972,45.135,675,25.9808,,0.070253955
36.09116142,45.135,599,24.4745,,0.06234388
36.16994311,45.135,598,24.454,,0.0622398
36.24872481,45.135,651,25.5147,,0.067756037
36.3275065,45.135,761,27.5862,,0.079204829
36.4062882,45.135,913,30.2159,,0.095024979
36.4850699,45.135,1454,38.1314,,0.151332223
36.56385159,45.135,3334,57.7408,,0.347002498
36.64263329,45.135,7786,88.2383,,0.810366361
36.72141498,45.135,9608,98.0204,,1
36.80019668,45.135,6429,80.181,,0.669129892
36.87897838,45.135,2785,52.7731,,0.289862614
36.95776007,45.135,1120,33.4664,,0.116569525
37.03654177,45.135,810,28.4605,,0.084304746
37.11532347,45.135,597,24.4336,,0.06213572
37.19410516,45.135,535,23.1301,,0.055682764
37.27288686,45.135,526,22.9347,,0.054746045
37.35166855,45.135,448,21.166,,0.04662781
37.43045025,45.135,487,22.0681,,0.050686928
37.50923195,45.135,462,21.4942,,0.048084929
37.58801364,45.135,434,20.8327,,0.045170691
37.66679534,45.135,406,20.1494,,0.042256453
37.74557703,45.135,408,20.199,,0.042464613
37.82435873,45.135,389,19.7231,,0.040487094
37.90314043,45.135,385,19.6214,,0.040070774
37.98192212,45.135,357,18.8944,,0.037156536
38.06070382,45.135,392,19.799,,0.040799334
38.13948551,45.135,346,18.6011,,0.036011657
38.21826721,45.135,395,19.8746,,0.041111574
38.29704891,45.135,386,19.6469,,0.040174854
38.3758306,45.135,379,19.4679,,0.039446295
38.4546123,45.135,381,19.5192,,0.039654455
38.53339399,45.135,317,17.8045,,0.032993339
38.61217569,45.135,360,18.9737,,0.037468776
38.69095739,45.135,345,18.5742,,0.035907577
38.76973908,45.135,384,19.5959,,0.039966694
38.84852078,45.135,375,19.3649,,0.039029975
38.92730247,45.135,334,18.2757,,0.034762698
39.00608417,45.135,357,18.8944,,0.037156536
39.08486587,45.135,346,18.6011,,0.036011657
39.16364756,45.135,382,19.5448,,0.039758535
39.24242926,45.135,350,18.7083,,0.036427977
39.32121095,45.135,380,19.4936,,0.039550375
39.39999265,45.135,363,19.0526,,0.037781016
39.47877435,45.135,351,18.735,,0.036532057
39.55755604,45.135,352,18.7617,,0.036636137
39.63633774,45.135,396,19.8997,,0.041215654
39.71511943,45.135,387,19.6723,,0.040278934
39.79390113,45.135,391,19.7737,,0.040695254
39.87268283,45.135,450,21.2132,,0.04683597
39.95146452,45.135,433,20.8087,,0.045066611
40.03024622,45.135,466,21.587,,0.048501249
40.10902792,45.135,429,20.7123,,0.044650291
40.18780961,45.135,407,20.1742,,0.042360533
40.26659131,45.135,388,19.6977,,0.040383014
40.345373,45.135,353,18.7883,,0.036740216
40.4241547,45.135,343,18.5203,,0.035699417
40.5029364,45.135,345,18.5742,,0.035907577
40.58171809,45.135,361,19,,0.037572856
40.66049979,45.135,376,19.3907,,0.039134055
40.73928148,45.135,372,19.2873,,0.038717735
40.81806318,45.135,328,18.1108,,0.034138218
40.89684488,45.135,335,18.303,,0.034866778
40.97562657,45.135,358,18.9209,,0.037260616
41.05440827,45.135,309,17.5784,,0.032160699
41.13318996,45.135,343,18.5203,,0.035699417
41.21197166,45.135,360,18.9737,,0.037468776
41.29075336,45.135,380,19.4936,,0.039550375
41.36953505,45.135,323,17.9722,,0.033617818
41.44831675,45.135,340,18.4391,,0.035387177
41.52709844,45.135,351,18.735,,0.036532057
41.60588014,45.135,353,18.7883,,0.036740216
41.68466184,45.135,362,19.0263,,0.037676936
41.76344353,45.135,351,18.735,,0.036532057
41.84222523,45.135,336,18.3303,,0.034970858
41.92100692,45.135,319,17.8606,,0.033201499
41.99978862,45.135,322,17.9444,,0.033513739
42.07857032,45.135,330,18.1659,,0.034346378
42.15735201,45.135,361,19,,0.037572856
42.23613371,45.135,365,19.105,,0.037989176
42.3149154,45.135,343,18.5203,,0.035699417
42.3936971,45.135,346,18.6011,,0.036011657
42.4724788,45.135,342,18.4932,,0.035595337
42.55126049,45.135,386,19.6469,,0.040174854
42.63004219,45.135,345,18.5742,,0.035907577
42.70882389,45.135,330,18.1659,,0.034346378
42.78760558,45.135,331,18.1934,,0.034450458
42.86638728,45.135,346,18.6011,,0.036011657
42.94516897,45.135,324,18,,0.033721898
43.02395067,45.135,345,18.5742,,0.035907577
43.10273237,45.135,350,18.7083,,0.036427977
43.18151406,45.135,335,18.303,,0.034866778
43.26029576,45.135,330,18.1659,,0.034346378
43.33907745,45.135,353,18.7883,,0.036740216
43.41785915,45.135,376,19.3907,,0.039134055
43.49664085,45.135,368,19.1833,,0.038301415
43.57542254,45.135,350,18.7083,,0.036427977
43.65420424,45.135,353,18.7883,,0.036740216
43.73298593,45.135,359,18.9473,,0.037364696
43.81176763,45.135,317,17.8045,,0.032993339
43.89054933,45.135,338,18.3848,,0.035179017
43.96933102,45.135,303,17.4069,,0.03153622
44.04811272,45.135,323,17.9722,,0.033617818
44.12689441,45.135,311,17.6352,,0.032368859
44.20567611,45.135,329,18.1384,,0.034242298
44.28445781,45.135,318,17.8326,,0.033097419
44.3632395,45.135,312,17.6635,,0.032472939
44.4420212,45.135,337,18.3576,,0.035074938
44.52080289,45.135,314,17.72,,0.032681099
44.59958459,45.135,321,17.9165,,0.033409659
44.67836629,45.135,285,16.8819,,0.029662781
44.75714798,45.135,328,18.1108,,0.034138218
44.83592968,45.135,338,18.3848,,0.035179017
44.91471137,45.135,344,18.5472,,0.035803497
44.99349307,45.135,329,18.1384,,0.034242298
45.07227477,45.135,312,17.6635,,0.032472939
45.15105646,45.135,323,17.9722,,0.033617818
45.22983816,45.135,332,18.2209,,0.034554538
45.30861986,45.135,343,18.5203,,0.035699417
45.38740155,45.135,334,18.2757,,0.034762698
45.46618325,45.135,272,16.4924,,0.028309742
45.54496494,45.135,282,16.7929,,0.029350541
45.62374664,45.135,271,16.4621,,0.028205662
45.70252834,45.135,315,17.7482,,0.032785179
45.78131003,45.135,291,17.0587,,0.030287261
45.86009173,45.135,298,17.2627,,0.03101582
45.93887342,45.135,301,17.3494,,0.03132806
46.01765512,45.135,286,16.9115,,0.029766861
46.09643682,45.135,317,17.8045,,0.032993339
46.17521851,45.135,293,17.1172,,0.03049542
46.25400021,45.135,309,17.5784,,0.032160699
46.3327819,45.135,334,18.2757,,0.034762698
46.4115636,45.135,297,17.2337,,0.03091174
46.4903453,45.135,300,17.3205,,0.03122398
46.56912699,45.135,290,17.0294,,0.030183181
46.64790869,45.135,322,17.9444,,0.033513739
46.72669038,45.135,277,16.6433,,0.028830142
46.80547208,45.135,309,17.5784,,0.032160699
46.88425378,45.135,271,16.4621,,0.028205662
46.96303547,45.135,333,18.2483,,0.034658618
47.04181717,45.135,309,17.5784,,0.032160699
47.12059886,45.135,295,17.1756,,0.03070358
47.19938056,45.135,344,18.5472,,0.035803497
47.27816226,45.135,324,18,,0.033721898
47.35694395,45.135,349,18.6815,,0.036323897
47.43572565,45.135,357,18.8944,,0.037156536
47.51450734,45.135,385,19.6214,,0.040070774
47.59328904,45.135,363,19.0526,,0.037781016
47.67207074,45.135,440,20.9762,,0.045795171
47.75085243,45.135,643,25.3574,,0.066923397
47.82963413,45.135,1038,32.218,,0.108034971
47.90841582,45.135,1336,36.5513,,0.139050791
47.98719752,45.135,1111,33.3317,,0.115632806
48.06597922,45.135,729,27,,0.075874271
48.14476091,45.135,496,22.2711,,0.051623647
48.22354261,45.135,404,20.0998,,0.042048293
48.30232431,45.135,353,18.7883,,0.036740216
48.381106,45.135,341,18.4662,,0.035491257
48.4598877,45.135,317,17.8045,,0.032993339
48.53866939,45.135,316,17.7764,,0.032889259
48.61745109,45.135,287,16.9411,,0.029870941
48.69623279,45.135,333,18.2483,,0.034658618
48.77501448,45.135,328,18.1108,,0.034138218
48.85379618,45.135,305,17.4642,,0.03174438
48.93257787,45.135,301,17.3494,,0.03132806
49.01135957,45.135,297,17.2337,,0.03091174
49.09014127,45.135,278,16.6733,,0.028934221
49.16892296,45.135,296,17.2047,,0.03080766
49.24770466,45.135,276,16.6132,,0.028726062
49.32648635,45.135,309,17.5784,,0.032160699
49.40526805,45.135,286,16.9115,,0.029766861
49.48404975,45.135,292,17.088,,0.030391341
49.56283144,45.135,292,17.088,,0.030391341
49.64161314,45.135,321,17.9165,,0.033409659
49.72039483,45.135,285,16.8819,,0.029662781
49.79917653,45.135,309,17.5784,,0.032160699
49.87795823,45.135,299,17.2916,,0.0311199
49.95673992,45.135,302,17.3781,,0.03143214
50.03552162,45.135,300,17.3205,,0.03122398
50.11430331,45.135,255,15.9687,,0.026540383
50.19308501,45.135,303,17.4069,,0.03153622
50.27186671,45.135,298,17.2627,,0.03101582
50.3506484,45.135,295,17.1756,,0.03070358
50.4294301,45.135,283,16.8226,,0.029454621
50.50821179,45.135,262,16.1864,,0.027268943
50.58699349,45.135,309,17.5784,,0.032160699
50.66577519,45.135,326,18.0555,,0.033930058
50.74455688,45.135,326,18.0555,,0.033930058
50.82333858,45.135,261,16.1555,,0.027164863
50.90212028,45.135,278,16.6733,,0.028934221
50.98090197,45.135,300,17.3205,,0.03122398
51.05968367,45.135,276,16.6132,,0.028726062
51.13846536,45.135,294,17.1464,,0.0305995
51.21724706,45.135,246,15.6844,,0.025603664
51.29602876,45.135,309,17.5784,,0.032160699
51.37481045,45.135,242,15.5563,,0.025187344
51.45359215,45.135,272,16.4924,,0.028309742
51.53237384,45.135,301,17.3494,,0.03132806
51.61115554,45.135,260,16.1245,,0.027060783
51.68993724,45.135,263,16.2173,,0.027373022
51.76871893,45.135,291,17.0587,,0.030287261
51.84750063,45.135,277,16.6433,,0.028830142
51.92628232,45.135,271,16.4621,,0.028205662
52.00506402,45.135,268,16.3707,,0.027893422
52.08384572,45.135,282,16.7929,,0.029350541
52.16262741,45.135,281,16.7631,,0.029246461
52.24140911,45.135,282,16.7929,,0.029350541
52.3201908,45.135,286,16.9115,,0.029766861
52.3989725,45.135,264,16.2481,,0.027477102
52.4777542,45.135,290,17.0294,,0.030183181
52.55653589,45.135,259,16.0935,,0.026956703
52.63531759,45.135,265,16.2788,,0.027581182
52.71409928,45.135,264,16.2481,,0.027477102
52.79288098,45.135,253,15.906,,0.026332223
52.87166268,45.135,253,15.906,,0.026332223
52.95044437,45.135,257,16.0312,,0.026748543
53.02922607,45.135,273,16.5227,,0.028413822
53.10800776,45.135,266,16.3095,,0.027685262
53.18678946,45.135,266,16.3095,,0.027685262
53.26557116,45.135,256,16,,0.026644463
53.34435285,45.135,249,15.7797,,0.025915903
53.42313455,45.135,292,17.088,,0.030391341
53.50191625,45.135,258,16.0624,,0.026852623
53.58069794,45.135,256,16,,0.026644463
53.65947964,45.135,259,16.0935,,0.026956703
53.73826133,45.135,286,16.9115,,0.029766861
53.81704303,45.135,258,16.0624,,0.026852623
53.89582473,45.135,251,15.843,,0.026124063
53.97460642,45.135,268,16.3707,,0.027893422
54.05338812,45.135,255,15.9687,,0.026540383
54.13216981,45.135,262,16.1864,,0.027268943
54.21095151,45.135,258,16.0624,,0.026852623
54.28973321,45.135,288,16.9706,,0.029975021
54.3685149,45.135,283,16.8226,,0.029454621
54.4472966,45.135,282,16.7929,,0.029350541
54.52607829,45.135,343,18.5203,,0.035699417
54.60485999,45.135,375,19.3649,,0.039029975
54.68364169,45.135,434,20.8327,,0.045170691
54.76242338,45.135,415,20.3715,,0.043193172
54.84120508,45.135,380,19.4936,,0.039550375
54.91998677,45.135,356,18.868,,0.037052456
54.99876847,45.135,349,18.6815,,0.036323897
55.07755017,45.135,280,16.7332,,0.029142381
55.15633186,45.135,319,17.8606,,0.033201499
55.23511356,45.135,274,16.5529,,0.028517902
55.31389525,45.135,270,16.4317,,0.028101582
55.39267695,45.135,268,16.3707,,0.027893422
55.47145865,45.135,252,15.8745,,0.026228143
55.55024034,45.135,263,16.2173,,0.027373022
55.62902204,45.135,247,15.7162,,0.025707744
55.70780373,45.135,248,15.748,,0.025811823
55.78658543,45.135,258,16.0624,,0.026852623
55.86536713,45.135,248,15.748,,0.025811823
55.94414882,45.135,256,16,,0.026644463
56.02293052,45.135,293,17.1172,,0.03049542
56.10171221,45.135,261,16.1555,,0.027164863
56.18049391,45.135,235,15.3297,,0.024458784
56.25927561,45.135,253,15.906,,0.026332223
56.3380573,45.135,277,16.6433,,0.028830142
56.416839,45.135,257,16.0312,,0.026748543
56.4956207,45.135,238,15.4272,,0.024771024
56.57440239,45.135,248,15.748,,0.025811823
56.65318409,45.135,266,16.3095,,0.027685262
56.73196578,45.135,235,15.3297,,0.024458784
56.81074748,45.135,266,16.3095,,0.027685262
56.88952918,45.135,275,16.5831,,0.028621982
56.96831087,45.135,256,16,,0.026644463
57.04709257,45.135,284,16.8523,,0.029558701
57.12587426,45.135,347,18.6279,,0.036115737
57.20465596,45.135,342,18.4932,,0.035595337
57.28343766,45.135,445,21.095,,0.04631557
57.36221935,45.135,818,28.6007,,0.085137386
57.44100105,45.135,1281,35.7911,,0.133326395
57.51978274,45.135,1104,33.2265,,0.114904246
57.59856444,45.135,810,28.4605,,0.084304746
57.67734614,45.135,539,23.2164,,0.056099084
57.75612783,45.135,378,19.4422,,0.039342215
57.83490953,45.135,315,17.7482,,0.032785179
57.91369122,45.135,315,17.7482,,0.032785179
57.99247292,45.135,269,16.4012,,0.027997502
58.07125462,45.135,239,15.4596,,0.024875104
58.15003631,45.135,280,16.7332,,0.029142381
58.22881801,45.135,288,16.9706,,0.029975021
58.3075997,45.135,260,16.1245,,0.027060783
58.3863814,45.135,215,14.6629,,0.022377186
58.4651631,45.135,256,16,,0.026644463
58.54394479,45.135,256,16,,0.026644463
58.62272649,45.135,218,14.7648,,0.022689425
58.70150818,45.135,221,14.8661,,0.023001665
58.78028988,45.135,229,15.1327,,0.023834305
58.85907158,45.135,255,15.9687,,0.026540383
58.93785327,45.135,231,15.1987,,0.024042465
59.01663497,45.135,234,15.2971,,0.024354704
59.09541667,45.135,241,15.5242,,0.025083264
59.17419836,45.135,219,14.7986,,0.022793505
59.25298006,45.135,239,15.4596,,0.024875104
59.33176175,45.135,253,15.906,,0.026332223
59.41054345,45.135,264,16.2481,,0.027477102
59.48932515,45.135,236,15.3623,,0.024562864
59.56810684,45.135,199,14.1067,,0.020711907
59.64688854,45.135,252,15.8745,,0.026228143
59.72567023,45.135,254,15.9374,,0.026436303
59.80445193,45.135,244,15.6205,,0.025395504
59.88323363,45.135,206,14.3527,,0.021440466
59.96201532,45.135,227,15.0665,,0.023626145
60.04079702,45.135,229,15.1327,,0.023834305
60.11957871,45.135,243,15.5885,,0.025291424
60.19836041,45.135,247,15.7162,,0.025707744
60.27714211,45.135,214,14.6287,,0.022273106
60.3559238,45.135,209,14.4568,,0.021752706
60.4347055,45.135,235,15.3297,,0.024458784
60.51348719,45.135,223,14.9332,,0.023209825
60.59226889,45.135,235,15.3297,,0.024458784
60.67105059,45.135,229,15.1327,,0.023834305
60.74983228,45.135,255,15.9687,,0.026540383
60.82861398,45.135,264,16.2481,,0.027477102
60.90739567,45.135,220,14.8324,,0.022897585
60.98617737,45.135,228,15.0997,,0.023730225
61.06495907,45.135,245,15.6525,,0.025499584
61.14374076,45.135,258,16.0624,,0.026852623
61.22252246,45.135,253,15.906,,0.026332223
61.30130415,45.135,266,16.3095,,0.027685262
61.38008585,45.135,258,16.0624,,0.026852623
61.45886755,45.135,235,15.3297,,0.024458784
61.53764924,45.135,241,15.5242,,0.025083264
61.61643094,45.135,251,15.843,,0.026124063
61.69521264,45.135,254,15.9374,,0.026436303
61.77399433,45.135,242,15.5563,,0.025187344
61.85277603,45.135,264,16.2481,,0.027477102
61.93155772,45.135,242,15.5563,,0.025187344
62.01033942,45.135,263,16.2173,,0.027373022
62.08912112,45.135,236,15.3623,,0.024562864
62.16790281,45.135,252,15.8745,,0.026228143
62.24668451,45.135,242,15.5563,,0.025187344
62.3254662,45.135,243,15.5885,,0.025291424
62.4042479,45.135,263,16.2173,,0.027373022
62.4830296,45.135,241,15.5242,,0.025083264
62.56181129,45.135,255,15.9687,,0.026540383
62.64059299,45.135,266,16.3095,,0.027685262
62.71937468,45.135,251,15.843,,0.026124063
62.79815638,45.135,322,17.9444,,0.033513739
62.87693808,45.135,317,17.8045,,0.032993339
62.95571977,45.135,406,20.1494,,0.042256453
63.03450147,45.135,658,25.6515,,0.068484596
63.11328316,45.135,977,31.257,,0.101686095
63.19206486,45.135,976,31.241,,0.101582015
63.27084656,45.135,796,28.2135,,0.082847627
63.34962825,45.135,640,25.2982,,0.066611157
63.42840995,45.135,413,20.3224,,0.042985012
63.50719164,45.135,308,17.5499,,0.032056619
63.58597334,45.135,329,18.1384,,0.034242298
63.66475504,45.135,243,15.5885,,0.025291424
63.74353673,45.135,269,16.4012,,0.027997502
63.82231843,45.135,253,15.906,,0.026332223
63.90110012,45.135,227,15.0665,,0.023626145
63.97988182,45.135,240,15.4919,,0.024979184
64.05866352,45.135,251,15.843,,0.026124063
64.13744521,45.135,244,15.6205,,0.025395504
64.21622691,45.135,208,14.4222,,0.021648626
64.2950086,45.135,216,14.6969,,0.022481266
64.3737903,45.135,230,15.1658,,0.023938385
64.452572,45.135,199,14.1067,,0.020711907
64.53135369,45.135,207,14.3875,,0.021544546
64.61013539,45.135,209,14.4568,,0.021752706
64.68891709,45.135,205,14.3178,,0.021336386
64.76769878,45.135,240,15.4919,,0.024979184
64.84648048,45.135,230,15.1658,,0.023938385
64.92526217,45.135,228,15.0997,,0.023730225
65.00404387,45.135,179,13.3791,,0.018630308
65.08282557,45.135,250,15.8114,,0.026019983
65.16160726,45.135,251,15.843,,0.026124063
65.24038896,45.135,272,16.4924,,0.028309742
65.31917065,45.135,219,14.7986,,0.022793505
65.39795235,45.135,244,15.6205,,0.025395504
65.47673405,45.135,237,15.3948,,0.024666944
65.55551574,45.135,214,14.6287,,0.022273106
65.63429744,45.135,239,15.4596,,0.024875104
65.71307913,45.135,207,14.3875,,0.021544546
65.79186083,45.135,224,14.9666,,0.023313905
65.87064253,45.135,200,14.1421,,0.020815987
65.94942422,45.135,213,14.5945,,0.022169026
66.02820592,45.135,206,14.3527,,0.021440466
66.10698761,45.135,213,14.5945,,0.022169026
66.18576931,45.135,221,14.8661,,0.023001665
66.26455101,45.135,209,14.4568,,0.021752706
66.3433327,45.135,240,15.4919,,0.024979184
66.4221144,45.135,214,14.6287,,0.022273106
66.50089609,45.135,224,14.9666,,0.023313905
66.57967779,45.135,208,14.4222,,0.021648626
66.65845949,45.135,208,14.4222,,0.021648626
66.73724118,45.135,180,13.4164,,0.018734388
66.81602288,45.135,192,13.8564,,0.019983347
66.89480457,45.135,251,15.843,,0.026124063
66.97358627,45.135,188,13.7113,,0.019567027
67.05236797,45.135,226,15.0333,,0.023522065
67.13114966,45.135,217,14.7309,,0.022585346
67.20993136,45.135,221,14.8661,,0.023001665
67.28871306,45.135,288,16.9706,,0.029975021
67.36749475,45.135,323,17.9722,,0.033617818
67.44627645,45.135,303,17.4069,,0.03153622
67.52505814,45.135,229,15.1327,,0.023834305
67.60383984,45.135,287,16.9411,,0.029870941
67.68262154,45.135,231,15.1987,,0.024042465
67.76140323,45.135,210,14.4914,,0.021856786
67.84018493,45.135,211,14.5258,,0.021960866
67.91896662,45.135,251,15.843,,0.026124063
67.99774832,45.135,248,15.748,,0.025811823
68.07653002,45.135,221,14.8661,,0.023001665
68.15531171,45.135,215,14.6629,,0.022377186
68.23409341,45.135,239,15.4596,,0.024875104
68.3128751,45.135,268,16.3707,,0.027893422
68.3916568,45.135,252,15.8745,,0.026228143
68.4704385,45.135,329,18.1384,,0.034242298
68.54922019,45.135,425,20.6155,,0.044233972
68.62800189,45.135,767,27.6948,,0.079829309
68.70678358,45.135,1016,31.8748,,0.105745212
68.78556528,45.135,779,27.9106,,0.081078268
68.86434698,45.135,679,26.0576,,0.070670275
68.94312867,45.135,549,23.4307,,0.057139883
69.02191037,45.135,359,18.9473,,0.037364696
69.10069206,45.135,292,17.088,,0.030391341
69.17947376,45.135,248,15.748,,0.025811823
69.25825546,45.135,229,15.1327,,0.023834305
69.33703715,45.135,237,15.3948,,0.024666944
69.41581885,45.135,233,15.2643,,0.024250624
69.49460054,45.135,207,14.3875,,0.021544546
69.57338224,45.135,249,15.7797,,0.025915903
69.65216394,45.135,243,15.5885,,0.025291424
69.73094563,45.135,264,16.2481,,0.027477102
69.80972733,45.135,247,15.7162,,0.025707744
69.88850903,45.135,302,17.3781,,0.03143214
69.96729072,45.135,482,21.9545,,0.050166528
70.04607242,45.135,646,25.4165,,0.067235637
70.12485411,45.135,711,26.6646,,0.074000833
70.20363581,45.135,490,22.1359,,0.050999167
70.28241751,45.135,516,22.7156,,0.053705246
70.3611992,45.135,335,18.303,,0.034866778
70.4399809,45.135,271,16.4621,,0.028205662
70.51876259,45.135,206,14.3527,,0.021440466
70.59754429,45.135,218,14.7648,,0.022689425
70.67632599,45.135,217,14.7309,,0.022585346
70.75510768,45.135,205,14.3178,,0.021336386
70.83388938,45.135,203,14.2478,,0.021128226
70.91267107,45.135,222,14.8997,,0.023105745
70.99145277,45.135,211,14.5258,,0.021960866
71.07023447,45.135,191,13.8203,,0.019879267
71.14901616,45.135,201,14.1774,,0.020920067
71.22779786,45.135,180,13.4164,,0.018734388
71.30657955,45.135,204,14.2829,,0.021232306
71.38536125,45.135,189,13.7477,,0.019671107
71.46414295,45.135,182,13.4907,,0.018942548
71.54292464,45.135,192,13.8564,,0.019983347
71.62170634,45.135,182,13.4907,,0.018942548
71.70048803,45.135,192,13.8564,,0.019983347
71.77926973,45.135,190,13.784,,0.019775187
71.85805143,45.135,191,13.8203,,0.019879267
71.93683312,45.135,188,13.7113,,0.019567027
72.01561482,45.135,202,14.2127,,0.021024147
72.09439651,45.135,168,12.9615,,0.017485429
72.17317821,45.135,173,13.1529,,0.018005828
72.25195991,45.135,206,14.3527,,0.021440466
72.3307416,45.135,179,13.3791,,0.018630308
72.4095233,45.135,212,14.5602,,0.022064946
72.488305,45.135,252,15.8745,,0.026228143
72.56708669,45.135,295,17.1756,,0.03070358
72.64586839,45.135,282,16.7929,,0.029350541
72.72465008,45.135,222,14.8997,,0.023105745
72.80343178,45.135,245,15.6525,,0.025499584
72.88221348,45.135,206,14.3527,,0.021440466
72.96099517,45.135,202,14.2127,,0.021024147
73.03977687,45.135,160,12.6491,,0.016652789
73.11855856,45.135,205,14.3178,,0.021336386
73.19734026,45.135,189,13.7477,,0.019671107
73.27612196,45.135,189,13.7477,,0.019671107
73.35490365,45.135,190,13.784,,0.019775187
73.43368535,45.135,204,14.2829,,0.021232306
73.51246704,45.135,196,14,,0.020399667
73.59124874,45.135,177,13.3041,,0.018422148
73.67003044,45.135,193,13.8924,,0.020087427
73.74881213,45.135,172,13.1149,,0.017901749
73.82759383,45.135,165,12.8452,,0.017173189
73.90637552,45.135,208,14.4222,,0.021648626
73.98515722,45.135,198,14.0712,,0.020607827
74.06393892,45.135,182,13.4907,,0.018942548
74.14272061,45.135,191,13.8203,,0.019879267
74.22150231,45.135,224,14.9666,,0.023313905
74.300284,45.135,153,12.3693,,0.01592423
74.3790657,45.135,192,13.8564,,0.019983347
74.4578474,45.135,154,12.4097,,0.01602831
74.53662909,45.135,169,13,,0.017589509
74.61541079,45.135,162,12.7279,,0.016860949
74.69419248,45.135,170,13.0384,,0.017693589
74.77297418,45.135,180,13.4164,,0.018734388
74.85175588,45.135,173,13.1529,,0.018005828
74.93053757,45.135,184,13.5647,,0.019150708
75.00931927,45.135,173,13.1529,,0.018005828
75.08810096,45.135,187,13.6748,,0.019462948
75.16688266,45.135,182,13.4907,,0.018942548
75.24566436,45.135,160,12.6491,,0.016652789
75.32444605,45.135,141,11.8743,,0.014675271
75.40322775,45.135,167,12.9228,,0.017381349
75.48200945,45.135,153,12.3693,,0.01592423
75.56079114,45.135,158,12.5698,,0.016444629
75.63957284,45.135,172,13.1149,,0.017901749
75.71835453,45.135,190,13.784,,0.019775187
75.79713623,45.135,182,13.4907,,0.018942548
75.87591793,45.135,182,13.4907,,0.018942548
75.95469962,45.135,159,12.6095,,0.016548709
76.03348132,45.135,183,13.5277,,0.019046628
76.11226301,45.135,179,13.3791,,0.018630308
76.19104471,45.135,169,13,,0.017589509
76.26982641,45.135,177,13.3041,,0.018422148
76.3486081,45.135,173,13.1529,,0.018005828
76.4273898,45.135,181,13.4536,,0.018838468
76.50617149,45.135,161,12.6886,,0.016756869
76.58495319,45.135,181,13.4536,,0.018838468
76.66373489,45.135,159,12.6095,,0.016548709
76.74251658,45.135,160,12.6491,,0.016652789
76.82129828,45.135,161,12.6886,,0.016756869
76.90007997,45.135,184,13.5647,,0.019150708
76.97886167,45.135,180,13.4164,,0.018734388
77.05764337,45.135,165,12.8452,,0.017173189
77.13642506,45.135,181,13.4536,,0.018838468
77.21520676,45.135,174,13.1909,,0.018109908
77.29398845,45.135,172,13.1149,,0.017901749
77.37277015,45.135,184,13.5647,,0.019150708
77.45155185,45.135,156,12.49,,0.01623647
77.53033354,45.135,160,12.6491,,0.016652789
77.60911524,45.135,179,13.3791,,0.018630308
77.68789693,45.135,212,14.5602,,0.022064946
77.76667863,45.135,187,13.6748,,0.019462948
77.84546033,45.135,263,16.2173,,0.027373022
77.92424202,45.135,268,16.3707,,0.027893422
78.00302372,45.135,238,15.4272,,0.024771024
78.08180542,45.135,220,14.8324,,0.022897585
78.16058711,45.135,213,14.5945,,0.022169026
78.23936881,45.135,189,13.7477,,0.019671107
78.3181505,45.135,201,14.1774,,0.020920067
78.3969322,45.135,183,13.5277,,0.019046628
78.4757139,45.135,176,13.2665,,0.018318068
78.55449559,45.135,178,13.3417,,0.018526228
78.63327729,45.135,161,12.6886,,0.016756869
78.71205898,45.135,175,13.2288,,0.018213988
78.79084068,45.135,160,12.6491,,0.016652789
78.86962238,45.135,183,13.5277,,0.019046628
78.94840407,45.135,178,13.3417,,0.018526228
79.02718577,45.135,174,13.1909,,0.018109908
79.10596746,45.135,164,12.8062,,0.017069109
79.18474916,45.135,180,13.4164,,0.018734388
79.26353086,45.135,170,13.0384,,0.017693589
79.34231255,45.135,181,13.4536,,0.018838468
79.42109425,45.135,179,13.3791,,0.018630308
79.49987594,45.135,168,12.9615,,0.017485429
79.57865764,45.135,147,12.1244,,0.01529975
79.65743934,45.135,150,12.2474,,0.01561199
79.73622103,45.135,169,13,,0.017589509
79.81500273,45.135,165,12.8452,,0.017173189
79.89378442,45.135,157,12.53,,0.01634055
79.97256612,45.135,143,11.9583,,0.01488343